<?xml version="1.0" ?>
<!-- =================================================================================== -->
<!-- |    This document was autogenerated by xacro from xacro/world_arm_1.xacro        | -->
<!-- |    EDITING THIS FILE BY HAND IS NOT RECOMMENDED                                 | -->
<!-- =================================================================================== -->
<robot name="world_arm_1">
  <!-- <xacro:walls_world/> -->
  <!-- <xacro:walls_world/> -->
  <link name="world_center"/>
  <link name="world"/>
  <joint name="world_center_to_world" type="fixed">
    <parent link="world_center"/>
    <child link="world"/>
    <origin rpy="0 0 0" xyz="0 0 0"/>
  </joint>
  <link name="base">
    <visual>
      <origin rpy="0 0 0" xyz="0 0 0.5"/>
      <geometry>
        <box size="2 2 1"/>
      </geometry>
      <material name="White">
        <color rgba="1.0 1.0 1.0 1.0"/>
      </material>
    </visual>
    <collision>
      <origin rpy="0 0 0" xyz="0 0 0.5"/>
      <geometry>
        <box size="2 2 1"/>
      </geometry>
    </collision>
    <inertial>
      <origin rpy="0.0 0.0 0.0" xyz="0.0 0.0 0.0"/>
      <mass value="10.0"/>
      <inertia ixx="0.001" ixy="0.0" ixz="0.001" iyy="0.0" iyz="0.0" izz="0.001"/>
    </inertial>
  </link>
  <joint name="base_to_world" type="fixed">
    <parent link="world"/>
    <child link="base"/>
    <origin rpy="0.0 0.0 0.0" xyz="0.0 0.0 0.0"/>
  </joint>
  <joint name="arm_1_joint_base" type="fixed">
    <parent link="base"/>
    <child link="arm_1_link0"/>
    <origin rpy="0 0 0" xyz="-0.5 0 1"/>
  </joint>
  <!-- sub-link defining detailed meshes for collision with environment -->
  <link name="arm_1_link0">
    <visual>
      <geometry>
        <mesh filename="package://franka_description/meshes/visual/link0.dae"/>
      </geometry>
    </visual>
    <collision>
      <geometry>
        <mesh filename="package://franka_description/meshes/collision/link0.stl"/>
      </geometry>
    </collision>
  </link>
  <!-- sub-link defining coarse geometries of real robot's internal self-collision -->
  <link name="arm_1_link0_sc">
    <collision>
      <origin rpy="0 1.5707963267948966 0" xyz="-0.075 0 0.06"/>
      <geometry>
        <cylinder length="0.03" radius="0.09"/>
      </geometry>
    </collision>
    <collision>
      <origin xyz="-0.06 0 0.06"/>
      <geometry>
        <sphere radius="0.09"/>
      </geometry>
    </collision>
    <collision>
      <origin xyz="-0.09 0 0.06"/>
      <geometry>
        <sphere radius="0.09"/>
      </geometry>
    </collision>
  </link>
  <!-- fixed joint between both sub-links -->
  <joint name="arm_1_link0_sc_joint" type="fixed">
    <origin rpy="0 0 0"/>
    <parent link="arm_1_link0"/>
    <child link="arm_1_link0_sc"/>
  </joint>
  <!-- sub-link defining detailed meshes for collision with environment -->
  <link name="arm_1_link1">
    <visual>
      <geometry>
        <mesh filename="package://franka_description/meshes/visual/link1.dae"/>
      </geometry>
    </visual>
    <collision>
      <geometry>
        <mesh filename="package://franka_description/meshes/collision/link1.stl"/>
      </geometry>
    </collision>
  </link>
  <!-- sub-link defining coarse geometries of real robot's internal self-collision -->
  <link name="arm_1_link1_sc">
    <collision>
      <origin rpy="0 0 0" xyz="0 0 -0.1915"/>
      <geometry>
        <cylinder length="0.283" radius="0.09"/>
      </geometry>
    </collision>
    <collision>
      <origin xyz="0 0 -0.05000000000000002"/>
      <geometry>
        <sphere radius="0.09"/>
      </geometry>
    </collision>
    <collision>
      <origin xyz="0 0 -0.33299999999999996"/>
      <geometry>
        <sphere radius="0.09"/>
      </geometry>
    </collision>
  </link>
  <!-- fixed joint between both sub-links -->
  <joint name="arm_1_link1_sc_joint" type="fixed">
    <origin rpy="0 0 0"/>
    <parent link="arm_1_link1"/>
    <child link="arm_1_link1_sc"/>
  </joint>
  <joint name="arm_1_1" type="revolute">
    <origin rpy="0 0 0" xyz="0 0 0.333"/>
    <parent link="arm_1_link0"/>
    <child link="arm_1_link1"/>
    <axis xyz="0 0 1"/>
    <limit effort="87.0" lower="-2.8973" upper="2.8973" velocity="2.175"/>
    <safety_controller k_position="100.0" k_velocity="40.0" soft_lower_limit="-2.8973" soft_upper_limit="2.8973"/>
    <dynamics D="1" K="7000" damping="0.003" friction="0.0" mu_coulomb="0" mu_viscous="16"/>
  </joint>
  <!-- sub-link defining detailed meshes for collision with environment -->
  <link name="arm_1_link2">
    <visual>
      <geometry>
        <mesh filename="package://franka_description/meshes/visual/link2.dae"/>
      </geometry>
    </visual>
    <collision>
      <geometry>
        <mesh filename="package://franka_description/meshes/collision/link2.stl"/>
      </geometry>
    </collision>
  </link>
  <!-- sub-link defining coarse geometries of real robot's internal self-collision -->
  <link name="arm_1_link2_sc">
    <collision>
      <origin rpy="0 0 0" xyz="0 0 0"/>
      <geometry>
        <cylinder length="0.12" radius="0.09"/>
      </geometry>
    </collision>
    <collision>
      <origin xyz="0 0 0.06"/>
      <geometry>
        <sphere radius="0.09"/>
      </geometry>
    </collision>
    <collision>
      <origin xyz="0 0 -0.06"/>
      <geometry>
        <sphere radius="0.09"/>
      </geometry>
    </collision>
  </link>
  <!-- fixed joint between both sub-links -->
  <joint name="arm_1_link2_sc_joint" type="fixed">
    <origin rpy="0 0 0"/>
    <parent link="arm_1_link2"/>
    <child link="arm_1_link2_sc"/>
  </joint>
  <joint name="arm_1_2" type="revolute">
    <origin rpy="-1.5707963267948966 0 0" xyz="0 0 0"/>
    <parent link="arm_1_link1"/>
    <child link="arm_1_link2"/>
    <axis xyz="0 0 1"/>
    <limit effort="87.0" lower="-1.7628" upper="1.7628" velocity="2.175"/>
    <safety_controller k_position="100.0" k_velocity="40.0" soft_lower_limit="-1.7628" soft_upper_limit="1.7628"/>
    <dynamics D="1" K="7000" damping="0.003" friction="0.0" mu_coulomb="0" mu_viscous="16"/>
  </joint>
  <!-- sub-link defining detailed meshes for collision with environment -->
  <link name="arm_1_link3">
    <visual>
      <geometry>
        <mesh filename="package://franka_description/meshes/visual/link3.dae"/>
      </geometry>
    </visual>
    <collision>
      <geometry>
        <mesh filename="package://franka_description/meshes/collision/link3.stl"/>
      </geometry>
    </collision>
  </link>
  <!-- sub-link defining coarse geometries of real robot's internal self-collision -->
  <link name="arm_1_link3_sc">
    <collision>
      <origin rpy="0 0 0" xyz="0 0 -0.145"/>
      <geometry>
        <cylinder length="0.15" radius="0.09"/>
      </geometry>
    </collision>
    <collision>
      <origin xyz="0 0 -0.06999999999999999"/>
      <geometry>
        <sphere radius="0.09"/>
      </geometry>
    </collision>
    <collision>
      <origin xyz="0 0 -0.21999999999999997"/>
      <geometry>
        <sphere radius="0.09"/>
      </geometry>
    </collision>
  </link>
  <!-- fixed joint between both sub-links -->
  <joint name="arm_1_link3_sc_joint" type="fixed">
    <origin rpy="0 0 0"/>
    <parent link="arm_1_link3"/>
    <child link="arm_1_link3_sc"/>
  </joint>
  <joint name="arm_1_3" type="revolute">
    <origin rpy="1.5707963267948966 0 0" xyz="0 -0.316 0"/>
    <parent link="arm_1_link2"/>
    <child link="arm_1_link3"/>
    <axis xyz="0 0 1"/>
    <limit effort="87.0" lower="-2.8973" upper="2.8973" velocity="2.175"/>
    <safety_controller k_position="100.0" k_velocity="40.0" soft_lower_limit="-2.8973" soft_upper_limit="2.8973"/>
    <dynamics D="1" K="7000" damping="0.003" friction="0.0" mu_coulomb="0" mu_viscous="16"/>
  </joint>
  <!-- sub-link defining detailed meshes for collision with environment -->
  <link name="arm_1_link4">
    <visual>
      <geometry>
        <mesh filename="package://franka_description/meshes/visual/link4.dae"/>
      </geometry>
    </visual>
    <collision>
      <geometry>
        <mesh filename="package://franka_description/meshes/collision/link4.stl"/>
      </geometry>
    </collision>
  </link>
  <!-- sub-link defining coarse geometries of real robot's internal self-collision -->
  <link name="arm_1_link4_sc">
    <collision>
      <origin rpy="0 0 0" xyz="0 0 0"/>
      <geometry>
        <cylinder length="0.12" radius="0.09"/>
      </geometry>
    </collision>
    <collision>
      <origin xyz="0 0 0.06"/>
      <geometry>
        <sphere radius="0.09"/>
      </geometry>
    </collision>
    <collision>
      <origin xyz="0 0 -0.06"/>
      <geometry>
        <sphere radius="0.09"/>
      </geometry>
    </collision>
  </link>
  <!-- fixed joint between both sub-links -->
  <joint name="arm_1_link4_sc_joint" type="fixed">
    <origin rpy="0 0 0"/>
    <parent link="arm_1_link4"/>
    <child link="arm_1_link4_sc"/>
  </joint>
  <joint name="arm_1_4" type="revolute">
    <origin rpy="1.5707963267948966 0 0" xyz="0.0825 0 0"/>
    <parent link="arm_1_link3"/>
    <child link="arm_1_link4"/>
    <axis xyz="0 0 1"/>
    <limit effort="87.0" lower="-3.0718" upper="-0.0698" velocity="2.175"/>
    <safety_controller k_position="100.0" k_velocity="40.0" soft_lower_limit="-3.0718" soft_upper_limit="-0.0698"/>
    <dynamics D="1" K="7000" damping="0.003" friction="0.0" mu_coulomb="0" mu_viscous="16"/>
  </joint>
  <!-- sub-link defining detailed meshes for collision with environment -->
  <link name="arm_1_link5">
    <visual>
      <geometry>
        <mesh filename="package://franka_description/meshes/visual/link5.dae"/>
      </geometry>
    </visual>
    <collision>
      <geometry>
        <mesh filename="package://franka_description/meshes/collision/link5.stl"/>
      </geometry>
    </collision>
  </link>
  <!-- sub-link defining coarse geometries of real robot's internal self-collision -->
  <link name="arm_1_link5_sc">
    <collision>
      <origin rpy="0 0 0" xyz="0 0 -0.26"/>
      <geometry>
        <cylinder length="0.1" radius="0.09"/>
      </geometry>
    </collision>
    <collision>
      <origin xyz="0 0 -0.21000000000000002"/>
      <geometry>
        <sphere radius="0.09"/>
      </geometry>
    </collision>
    <collision>
      <origin xyz="0 0 -0.31"/>
      <geometry>
        <sphere radius="0.09"/>
      </geometry>
    </collision>
    <collision>
      <origin rpy="0 0 0.08" xyz="0 0.08 -0.13"/>
      <geometry>
        <cylinder length="0.14" radius="0.055"/>
      </geometry>
    </collision>
    <collision>
      <origin xyz="0 0.08 -0.06"/>
      <geometry>
        <sphere radius="0.055"/>
      </geometry>
    </collision>
    <collision>
      <origin xyz="0 0.08 -0.2"/>
      <geometry>
        <sphere radius="0.055"/>
      </geometry>
    </collision>
  </link>
  <!-- fixed joint between both sub-links -->
  <joint name="arm_1_link5_sc_joint" type="fixed">
    <origin rpy="0 0 0"/>
    <parent link="arm_1_link5"/>
    <child link="arm_1_link5_sc"/>
  </joint>
  <joint name="arm_1_5" type="revolute">
    <origin rpy="-1.5707963267948966 0 0" xyz="-0.0825 0.384 0"/>
    <parent link="arm_1_link4"/>
    <child link="arm_1_link5"/>
    <axis xyz="0 0 1"/>
    <limit effort="12.0" lower="-2.8973" upper="2.8973" velocity="2.61"/>
    <safety_controller k_position="100.0" k_velocity="40.0" soft_lower_limit="-2.8973" soft_upper_limit="2.8973"/>
    <dynamics D="1" K="7000" damping="0.003" friction="0.0" mu_coulomb="0" mu_viscous="16"/>
  </joint>
  <!-- sub-link defining detailed meshes for collision with environment -->
  <link name="arm_1_link6">
    <visual>
      <geometry>
        <mesh filename="package://franka_description/meshes/visual/link6.dae"/>
      </geometry>
    </visual>
    <collision>
      <geometry>
        <mesh filename="package://franka_description/meshes/collision/link6.stl"/>
      </geometry>
    </collision>
  </link>
  <!-- sub-link defining coarse geometries of real robot's internal self-collision -->
  <link name="arm_1_link6_sc">
    <collision>
      <origin rpy="0 0 0" xyz="0 0 -0.03"/>
      <geometry>
        <cylinder length="0.08" radius="0.08"/>
      </geometry>
    </collision>
    <collision>
      <origin xyz="0 0 0.010000000000000002"/>
      <geometry>
        <sphere radius="0.08"/>
      </geometry>
    </collision>
    <collision>
      <origin xyz="0 0 -0.07"/>
      <geometry>
        <sphere radius="0.08"/>
      </geometry>
    </collision>
  </link>
  <!-- fixed joint between both sub-links -->
  <joint name="arm_1_link6_sc_joint" type="fixed">
    <origin rpy="0 0 0"/>
    <parent link="arm_1_link6"/>
    <child link="arm_1_link6_sc"/>
  </joint>
  <joint name="arm_1_6" type="revolute">
    <origin rpy="1.5707963267948966 0 0" xyz="0 0 0"/>
    <parent link="arm_1_link5"/>
    <child link="arm_1_link6"/>
    <axis xyz="0 0 1"/>
    <limit effort="12.0" lower="-0.0175" upper="3.7525" velocity="2.61"/>
    <safety_controller k_position="100.0" k_velocity="40.0" soft_lower_limit="-0.0175" soft_upper_limit="3.7525"/>
    <dynamics D="1" K="7000" damping="0.003" friction="0.0" mu_coulomb="0" mu_viscous="16"/>
  </joint>
  <!-- sub-link defining detailed meshes for collision with environment -->
  <link name="arm_1_link7">
    <visual>
      <geometry>
        <mesh filename="package://franka_description/meshes/visual/link7.dae"/>
      </geometry>
    </visual>
    <collision>
      <geometry>
        <mesh filename="package://franka_description/meshes/collision/link7.stl"/>
      </geometry>
    </collision>
  </link>
  <!-- sub-link defining coarse geometries of real robot's internal self-collision -->
  <link name="arm_1_link7_sc">
    <collision>
      <origin rpy="0 0 0" xyz="0 0 0.01"/>
      <geometry>
        <cylinder length="0.14" radius="0.07"/>
      </geometry>
    </collision>
    <collision>
      <origin xyz="0 0 0.08"/>
      <geometry>
        <sphere radius="0.07"/>
      </geometry>
    </collision>
    <collision>
      <origin xyz="0 0 -0.060000000000000005"/>
      <geometry>
        <sphere radius="0.07"/>
      </geometry>
    </collision>
    <collision>
      <origin rpy="0 1.5707963267948966 0" xyz="0.06 0 0.082"/>
      <geometry>
        <cylinder length="0.01" radius="0.06"/>
      </geometry>
    </collision>
    <collision>
      <origin xyz="0.065 0 0.082"/>
      <geometry>
        <sphere radius="0.06"/>
      </geometry>
    </collision>
    <collision>
      <origin xyz="0.055 0 0.082"/>
      <geometry>
        <sphere radius="0.06"/>
      </geometry>
    </collision>
  </link>
  <!-- fixed joint between both sub-links -->
  <joint name="arm_1_link7_sc_joint" type="fixed">
    <origin rpy="0 0 0.7853981633974483"/>
    <parent link="arm_1_link7"/>
    <child link="arm_1_link7_sc"/>
  </joint>
  <joint name="arm_1_7" type="revolute">
    <origin rpy="1.5707963267948966 0 0" xyz="0.088 0 0"/>
    <parent link="arm_1_link6"/>
    <child link="arm_1_link7"/>
    <axis xyz="0 0 1"/>
    <limit effort="12.0" lower="-2.8973" upper="2.8973" velocity="2.61"/>
    <safety_controller k_position="100.0" k_velocity="40.0" soft_lower_limit="-2.8973" soft_upper_limit="2.8973"/>
    <dynamics D="1" K="7000" damping="0.003" friction="0.0" mu_coulomb="0" mu_viscous="16"/>
  </joint>
  <link name="arm_1_link8"/>
  <joint name="arm_1_8" type="fixed">
    <origin rpy="0 0 0" xyz="0 0 0.107"/>
    <parent link="arm_1_link7"/>
    <child link="arm_1_link8"/>
  </joint>
  <!-- <xacro:arg name="arm_id_2" default="arm_2" />
    <xacro:arm_robot arm_id="$(arg arm_id_2)" connected_to="base" xyz="0 0.5 1" rpy="0 0 -1.57" gazebo="false" safety_distance="0.03" joint_limits="${xacro.load_yaml('$(find franka_description)/robots/panda/joint_limits.yaml')}"/>

    <xacro:arg name="arm_id_3" default="arm_3" />
    <xacro:arm_robot arm_id="$(arg arm_id_3)" connected_to="base" xyz="0.5 0 1" rpy="0 0 3.1415" gazebo="false" safety_distance="0.03" joint_limits="${xacro.load_yaml('$(find franka_description)/robots/panda/joint_limits.yaml')}"/>

    <xacro:arg name="arm_id_4" default="arm_4" />
    <xacro:arm_robot arm_id="$(arg arm_id_4)" connected_to="base" xyz="0 -0.5 1" rpy="0 0 1.57" gazebo="false" safety_distance="0.03" joint_limits="${xacro.load_yaml('$(find franka_description)/robots/panda/joint_limits.yaml')}"/>


    <xacro:arg name="arm_id_5" default="arm_5" />
    <xacro:arm_robot arm_id="$(arg arm_id_5)" connected_to="base" xyz="0 -0.5 1" rpy="0 0 1.57" gazebo="false" safety_distance="0.03" joint_limits="${xacro.load_yaml('$(find franka_description)/robots/panda/joint_limits.yaml')}"/>

    <xacro:arg name="arm_id_6" default="arm_6" />
    <xacro:arm_robot arm_id="$(arg arm_id_6)" connected_to="base" xyz="0 -0.5 1" rpy="0 0 1.57" gazebo="false" safety_distance="0.03" joint_limits="${xacro.load_yaml('$(find franka_description)/robots/panda/joint_limits.yaml')}"/> -->
  <!-- <xacro:arm_robot arm_id="arm_1" connected_to="base" xyz="0 -0.5 1" gazebo="false" safety_distance="0.03" joint_limits="${xacro.load_yaml('$(find franka_description)/robots/panda/joint_limits.yaml')}"/> -->
  <!-- <xacro:franka_hand arm_id="$(arg arm_id_1)" rpy="0 0 ${-pi/4}" connected_to="$(arg arm_id_1)_link8" gazebo="true" safety_distance="0.03" /> -->
  <!-- <xacro:arm_robot name="arm_1" arm_id=  -->
  <!-- <xacro:mobile_robot name="mobile_1" dims="0.25" color="white"/> -->
  <!-- <link name="mobile_1_temp"/> -->
  <!-- Mobile Robot 1 -->
  <!-- Joint x -->
  <!-- <joint name="mobile_1_1" type="prismatic">  -->
  <!-- <parent link="world"/> -->
  <!-- <child link="mobile_1_temp"/> -->
  <!-- <limit effort="1000.0" lower="0" upper="10" velocity="1"/> -->
  <!-- <axis xyz="1 0 0"/> -->
  <!-- <origin rpy="0 0 0" xyz="0 0 0"/> -->
  <!-- </joint> -->
  <!-- Joint y -->
  <!-- <joint name="mobile_1_2" type="prismatic"> -->
  <!-- <parent link="mobile_1_temp"/> -->
  <!-- <child link="mobile_1"/> -->
  <!-- <limit effort="1000.0" lower="0" upper="10" velocity="1"/> -->
  <!-- <axis xyz="0 1 0"/> -->
  <!-- <origin rpy="0 0 0" xyz="0 0 0"/> -->
  <!-- </joint> -->
</robot>
