<?xml version="1.0" ?>
<!-- =================================================================================== -->
<!-- |    This document was autogenerated by xacro from xacro/world_mobile_1_arm_6.xacro | -->
<!-- |    EDITING THIS FILE BY HAND IS NOT RECOMMENDED                                 | -->
<!-- =================================================================================== -->
<robot name="world_mobile_1">
  <!-- <xacro:walls_world_for_arms/> -->
  <material name="blue">
    <color rgba="0 0 0.8 1"/>
  </material>
  <material name="white">
    <color rgba="1 1 1 1"/>
  </material>
  <material name="green">
    <color rgba="0 0.8 0 1"/>
  </material>
  <material name="black">
    <color rgba="0 0 0 1"/>
  </material>
  <!-- Did not set a default for the name of the robot to require a name -->
  <!-- Follow the convention "mobile_1" -->
  <!-- Expected dims 0.25 unless the map changes -->
  <!-- <xacro:mobile_robot name="mobile_bot_1" dims="0.25" color="white"/> -->
  <link name="world_center"/>
  <link name="world"/>
  <joint name="world_center_to_world" type="fixed">
    <parent link="world_center"/>
    <child link="world"/>
    <origin rpy="0 0 0" xyz="-5.0 -5.0 0"/>
  </joint>
  <!-- Setup the first wall -->
  <link name="wall_right" type="fixed">
    <visual>
      <geometry>
        <box size="10.0 0.1 1"/>
      </geometry>
      <origin rpy="0 0 0" xyz="5.0 -0.060000000000000005 0"/>
    </visual>
    <collision>
      <geometry>
        <box size="10.0 0.1 1"/>
      </geometry>
      <origin rpy="0 0 0" xyz="5.0 -0.060000000000000005 0"/>
    </collision>
  </link>
  <joint name="world_to_right" type="fixed">
    <parent link="world"/>
    <child link="wall_right"/>
    <origin rpy="0 0 0" xyz="0 0 0.5"/>
  </joint>
  <!-- Setup the second wall -->
  <link name="wall_front">
    <visual>
      <geometry>
        <box size="10.0 0.1 1"/>
      </geometry>
      <origin rpy="0 0 0" xyz="5.0 -0.060000000000000005 0"/>
    </visual>
    <collision>
      <geometry>
        <box size="10.0 0.1 1"/>
      </geometry>
      <origin rpy="0 0 0" xyz="5.0 -0.060000000000000005 0"/>
    </collision>
  </link>
  <joint name="right_to_front" type="fixed">
    <parent link="wall_right"/>
    <child link="wall_front"/>
    <origin rpy="0 0 1.5708" xyz="10.0 0 0"/>
  </joint>
  <!-- Setup the third wall -->
  <link name="wall_left">
    <visual>
      <geometry>
        <box size="10.0 0.1 1"/>
      </geometry>
      <origin rpy="0 0 0" xyz="5.0 -0.060000000000000005 0"/>
    </visual>
    <collision>
      <geometry>
        <box size="10.0 0.1 1"/>
      </geometry>
      <origin rpy="0 0 0" xyz="5.0 -0.060000000000000005 0"/>
    </collision>
  </link>
  <joint name="front_to_left" type="fixed">
    <parent link="wall_front"/>
    <child link="wall_left"/>
    <origin rpy="0 0 1.5708" xyz="10.0 0 0"/>
  </joint>
  <!-- Setup the fourth wall -->
  <link name="wall_back">
    <visual>
      <geometry>
        <box size="10.0 0.1 1"/>
      </geometry>
      <origin rpy="0 0 0" xyz="5.0 -0.060000000000000005 0"/>
    </visual>
    <collision>
      <geometry>
        <box size="10.0 0.1 1"/>
      </geometry>
      <origin rpy="0 0 0" xyz="5.0 -0.060000000000000005 0"/>
    </collision>
  </link>
  <joint name="left_to_back" type="fixed">
    <parent link="wall_left"/>
    <child link="wall_back"/>
    <origin rpy="0 0 1.5708" xyz="10.0 0 0"/>
  </joint>
  <!-- Setup the first shelf -->
  <link name="shelf_1">
    <visual>
      <geometry>
        <box size="0.5 0.5 0.2"/>
      </geometry>
      <origin rpy="0 0 0" xyz="0 0 0.1"/>
    </visual>
    <collision>
      <geometry>
        <box size="0.5 0.5 0.2"/>
      </geometry>
      <origin rpy="0 0 0" xyz="0 0 0.1"/>
    </collision>
  </link>
  <joint name="world_to_shelf_1" type="fixed">
    <parent link="world"/>
    <child link="shelf_1"/>
    <origin rpy="0 0 0" xyz="2.5 3.3333333333333335 0"/>
  </joint>
  <!-- Setup the second shelf -->
  <link name="shelf_2">
    <visual>
      <geometry>
        <box size="0.5 0.5 0.2"/>
      </geometry>
      <origin rpy="0 0 0" xyz="0 0 0.1"/>
      0*radius}
      
    </visual>
    <collision>
      <geometry>
        <box size="0.5 0.5 0.2"/>
      </geometry>
      <origin rpy="0 0 0" xyz="0 0 0.1"/>
    </collision>
  </link>
  <joint name="world_to_shelf_2" type="fixed">
    <parent link="world"/>
    <child link="shelf_2"/>
    <origin rpy="0 0 0" xyz="5.0 3.3333333333333335 0"/>
  </joint>
  <!-- Setup the third shelf -->
  <link name="shelf_3">
    <visual>
      <geometry>
        <box size="0.5 0.5 0.2"/>
      </geometry>
      <origin rpy="0 0 0" xyz="0 0 0.1"/>
    </visual>
    <collision>
      <geometry>
        <box size="0.5 0.5 0.2"/>
      </geometry>
      <origin rpy="0 0 0" xyz="0 0 0.1"/>
    </collision>
  </link>
  <joint name="world_to_shelf_3" type="fixed">
    <parent link="world"/>
    <child link="shelf_3"/>
    <origin rpy="0 0 0" xyz="7.5 3.3333333333333335 0"/>
  </joint>
  <!-- Setup the fourth shelf -->
  <link name="shelf_4">
    <visual>
      <geometry>
        <box size="0.5 0.5 0.2"/>
      </geometry>
      <origin rpy="0 0 0" xyz="0 0 0.1"/>
    </visual>
    <collision>
      <geometry>
        <box size="0.5 0.5 0.2"/>
      </geometry>
      <origin rpy="0 0 0" xyz="0 0 0.1"/>
    </collision>
  </link>
  <joint name="world_to_shelf_4" type="fixed">
    <parent link="world"/>
    <child link="shelf_4"/>
    <origin rpy="0 0 0" xyz="2.5 6.666666666666667 0"/>
  </joint>
  <!-- Setup the fifth shelf -->
  <link name="shelf_5">
    <visual>
      <geometry>
        <box size="0.5 0.5 0.2"/>
      </geometry>
      <origin rpy="0 0 0" xyz="0 0 0.1"/>
    </visual>
    <collision>
      <geometry>
        <box size="0.5 0.5 0.2"/>
      </geometry>
      <origin rpy="0 0 0" xyz="0 0 0.1"/>
    </collision>
  </link>
  <joint name="world_to_shelf_5" type="fixed">
    <parent link="world"/>
    <child link="shelf_5"/>
    <origin rpy="0 0 0" xyz="5.0 6.666666666666667 0"/>
  </joint>
  <!-- Setup the sixth shelf -->
  <link name="shelf_6">
    <visual>
      <geometry>
        <box size="0.5 0.5 0.2"/>
      </geometry>
      <origin rpy="0 0 0" xyz="0 0 0.1"/>
    </visual>
    <collision>
      <geometry>
        <box size="0.5 0.5 0.2"/>
      </geometry>
      <origin rpy="0 0 0" xyz="0 0 0.1"/>
    </collision>
  </link>
  <joint name="world_to_shelf_6" type="fixed">
    <parent link="world"/>
    <child link="shelf_6"/>
    <origin rpy="0 0 0" xyz="7.5 6.666666666666667 0"/>
  </joint>
  <material name="pickup_shelf_color">
    <color rgba="0.5 0.5 0.5 0.99"/>
  </material>
  <link name="pickup_point_1">
    <visual>
      <geometry>
        <box size="0.5 0.5 1.3"/>
      </geometry>
      <material name="pickup_shelf_color"/>
      <origin rpy="0 0 0" xyz="0 0 0.65"/>
    </visual>
    <collision>
      <geometry>
        <box size="0.5 0.5 1.3"/>
      </geometry>
      <origin rpy="0 0 0" xyz="0 0 0.65"/>
    </collision>
  </link>
  <joint name="world_to_pickup_point_1" type="fixed">
    <parent link="world"/>
    <child link="pickup_point_1"/>
    <origin rpy="0 0 0" xyz="2.5 0.25 0"/>
  </joint>
  <link name="pickup_point_2">
    <visual>
      <geometry>
        <box size="0.5 0.5 1.3"/>
      </geometry>
      <material name="pickup_shelf_color"/>
      <origin rpy="0 0 0" xyz="0 0 0.65"/>
    </visual>
    <collision>
      <geometry>
        <box size="0.5 0.5 1.3"/>
      </geometry>
      <origin rpy="0 0 0" xyz="0 0 0.65"/>
    </collision>
  </link>
  <joint name="world_to_pickup_point_2" type="fixed">
    <parent link="world"/>
    <child link="pickup_point_2"/>
    <origin rpy="0 0 0" xyz="5.0 0.25 0"/>
  </joint>
  <link name="pickup_point_3">
    <visual>
      <geometry>
        <box size="0.5 0.5 1.3"/>
      </geometry>
      <material name="pickup_shelf_color"/>
      <origin rpy="0 0 0" xyz="0 0 0.65"/>
    </visual>
    <collision>
      <geometry>
        <box size="0.5 0.5 1.3"/>
      </geometry>
      <origin rpy="0 0 0" xyz="0 0 0.65"/>
    </collision>
  </link>
  <joint name="world_to_pickup_point_3" type="fixed">
    <parent link="world"/>
    <child link="pickup_point_3"/>
    <origin rpy="0 0 0" xyz="7.5 0.25 0"/>
  </joint>
  <link name="pickup_point_4">
    <visual>
      <geometry>
        <box size="0.5 0.5 1.3"/>
      </geometry>
      <material name="pickup_shelf_color"/>
      <origin rpy="0 0 0" xyz="0 0 0.65"/>
    </visual>
    <collision>
      <geometry>
        <box size="0.5 0.5 1.3"/>
      </geometry>
      <origin rpy="0 0 0" xyz="0 0 0.65"/>
    </collision>
  </link>
  <joint name="world_to_pickup_point_4" type="fixed">
    <parent link="world"/>
    <child link="pickup_point_4"/>
    <origin rpy="0 0 0" xyz="0.25 2.5 0"/>
  </joint>
  <link name="pickup_point_5">
    <visual>
      <geometry>
        <box size="0.5 0.5 1.3"/>
      </geometry>
      <material name="pickup_shelf_color"/>
      <origin rpy="0 0 0" xyz="0 0 0.65"/>
    </visual>
    <collision>
      <geometry>
        <box size="0.5 0.5 1.3"/>
      </geometry>
      <origin rpy="0 0 0" xyz="0 0 0.65"/>
    </collision>
  </link>
  <joint name="world_to_pickup_point_5" type="fixed">
    <parent link="world"/>
    <child link="pickup_point_5"/>
    <origin rpy="0 0 0" xyz="0.25 5.0 0"/>
  </joint>
  <link name="pickup_point_6">
    <visual>
      <geometry>
        <box size="0.5 0.5 1.3"/>
      </geometry>
      <material name="pickup_shelf_color"/>
      <origin rpy="0 0 0" xyz="0 0 0.65"/>
    </visual>
    <collision>
      <geometry>
        <box size="0.5 0.5 1.3"/>
      </geometry>
      <origin rpy="0 0 0" xyz="0 0 0.65"/>
    </collision>
  </link>
  <joint name="world_to_pickup_point_6" type="fixed">
    <parent link="world"/>
    <child link="pickup_point_6"/>
    <origin rpy="0 0 0" xyz="0.25 7.5 0"/>
  </joint>
  <link name="pickup_point_7">
    <visual>
      <geometry>
        <box size="0.5 0.5 1.3"/>
      </geometry>
      <material name="pickup_shelf_color"/>
      <origin rpy="0 0 0" xyz="0 0 0.65"/>
    </visual>
    <collision>
      <geometry>
        <box size="0.5 0.5 1.3"/>
      </geometry>
      <origin rpy="0 0 0" xyz="0 0 0.65"/>
    </collision>
  </link>
  <joint name="world_to_pickup_point_7" type="fixed">
    <parent link="world"/>
    <child link="pickup_point_7"/>
    <origin rpy="0 0 0" xyz="2.5 9.75 0"/>
  </joint>
  <link name="pickup_point_8">
    <visual>
      <geometry>
        <box size="0.5 0.5 1.3"/>
      </geometry>
      <material name="pickup_shelf_color"/>
      <origin rpy="0 0 0" xyz="0 0 0.65"/>
    </visual>
    <collision>
      <geometry>
        <box size="0.5 0.5 1.3"/>
      </geometry>
      <origin rpy="0 0 0" xyz="0 0 0.65"/>
    </collision>
  </link>
  <joint name="world_to_pickup_point_8" type="fixed">
    <parent link="world"/>
    <child link="pickup_point_8"/>
    <origin rpy="0 0 0" xyz="5.0 9.75 0"/>
  </joint>
  <link name="pickup_point_9">
    <visual>
      <geometry>
        <box size="0.5 0.5 1.3"/>
      </geometry>
      <material name="pickup_shelf_color"/>
      <origin rpy="0 0 0" xyz="0 0 0.65"/>
    </visual>
    <collision>
      <geometry>
        <box size="0.5 0.5 1.3"/>
      </geometry>
      <origin rpy="0 0 0" xyz="0 0 0.65"/>
    </collision>
  </link>
  <joint name="world_to_pickup_point_9" type="fixed">
    <parent link="world"/>
    <child link="pickup_point_9"/>
    <origin rpy="0 0 0" xyz="7.5 9.75 0"/>
  </joint>
  <!-- ############# -->
  <!-- Dropoff point -->
  <!-- ############# -->
  <link name="dropoff_point">
    <visual>
      <geometry>
        <box size="0.5 2 1.3"/>
      </geometry>
      <!-- <material name="pickup_shelf_color"/> -->
      <origin rpy="0 0 0" xyz="0 0 0.65"/>
    </visual>
    <collision>
      <geometry>
        <box size="0.5 2 1.3"/>
      </geometry>
      <origin rpy="0 0 0" xyz="0 0 0.65"/>
    </collision>
  </link>
  <joint name="world_to_dropoff_point" type="fixed">
    <parent link="world"/>
    <child link="dropoff_point"/>
    <origin rpy="0 0 0" xyz="9.75 5.0 0"/>
  </joint>
  <link default="mobile_bot_unnamed" name="mobile_1">
    <visual>
      <geometry>
        <cylinder length="0.5" radius="0.25"/>
      </geometry>
      <material name="white"/>
      <origin rpy="0 0 0" xyz="0 0 0.25"/>
    </visual>
    <collision>
      <geometry>
        <cylinder length="0.5" radius="0.25"/>
      </geometry>
      <origin rpy="0 0 0" xyz="0 0 0.25"/>
    </collision>
  </link>
  <link name="mobile_1_temp"/>
  <!-- Mobile Robot 1 -->
  <!-- Joint x -->
  <joint name="mobile_1_1" type="prismatic">
    <parent link="world"/>
    <child link="mobile_1_temp"/>
    <limit effort="1000.0" lower="0" upper="10" velocity="1"/>
    <axis xyz="1 0 0"/>
    <origin rpy="0 0 0" xyz="0 0 0"/>
  </joint>
  <!-- Joint y -->
  <joint name="mobile_1_2" type="prismatic">
    <parent link="mobile_1_temp"/>
    <child link="mobile_1"/>
    <limit effort="1000.0" lower="0" upper="10" velocity="1"/>
    <axis xyz="0 1 0"/>
    <origin rpy="0 0 0" xyz="0 0 0"/>
  </joint>
  <joint name="arm_1_joint_shelf_1" type="fixed">
    <parent link="shelf_1"/>
    <child link="arm_1_link0"/>
    <origin rpy="0 0 0" xyz="0 0 0.2"/>
  </joint>
  <!-- sub-link defining detailed meshes for collision with environment -->
  <link name="arm_1_link0">
    <visual>
      <geometry>
        <mesh filename="package://franka_description/meshes/visual/link0.dae"/>
      </geometry>
    </visual>
    <collision>
      <geometry>
        <mesh filename="package://franka_description/meshes/collision/link0.stl"/>
      </geometry>
    </collision>
  </link>
  <!-- sub-link defining coarse geometries of real robot's internal self-collision -->
  <!-- <link name="${prefix}${name}_sc">
      <xacro:unless value="${gazebo}">
        <xacro:insert_block name="self_collision_geometries" />
      </xacro:unless>
    </link> -->
  <!-- fixed joint between both sub-links -->
  <!-- <joint name="${prefix}${name}_sc_joint" type="fixed">
      <origin rpy="${rpy}" />
      <parent link="${prefix}${name}" />
      <child link="${prefix}${name}_sc" />
    </joint>
     -->
  <!-- Trying to remove the sc joints -->
  <!-- <joint name="${prefix}${name}_sc_joint" type="fixed"> -->
  <!-- <origin rpy="${rpy}" /> -->
  <!-- <parent link="${prefix}${name}" /> -->
  <!-- <child link="${prefix}${name}_sc" /> -->
  <!-- </joint> -->
  <!-- sub-link defining detailed meshes for collision with environment -->
  <link name="arm_1_link1">
    <visual>
      <geometry>
        <mesh filename="package://franka_description/meshes/visual/link1.dae"/>
      </geometry>
    </visual>
    <collision>
      <geometry>
        <mesh filename="package://franka_description/meshes/collision/link1.stl"/>
      </geometry>
    </collision>
  </link>
  <!-- sub-link defining coarse geometries of real robot's internal self-collision -->
  <!-- <link name="${prefix}${name}_sc">
      <xacro:unless value="${gazebo}">
        <xacro:insert_block name="self_collision_geometries" />
      </xacro:unless>
    </link> -->
  <!-- fixed joint between both sub-links -->
  <!-- <joint name="${prefix}${name}_sc_joint" type="fixed">
      <origin rpy="${rpy}" />
      <parent link="${prefix}${name}" />
      <child link="${prefix}${name}_sc" />
    </joint>
     -->
  <!-- Trying to remove the sc joints -->
  <!-- <joint name="${prefix}${name}_sc_joint" type="fixed"> -->
  <!-- <origin rpy="${rpy}" /> -->
  <!-- <parent link="${prefix}${name}" /> -->
  <!-- <child link="${prefix}${name}_sc" /> -->
  <!-- </joint> -->
  <joint name="arm_1_1" type="revolute">
    <origin rpy="0 0 0" xyz="0 0 0.333"/>
    <parent link="arm_1_link0"/>
    <child link="arm_1_link1"/>
    <axis xyz="0 0 1"/>
    <limit effort="87.0" lower="-2.8973" upper="2.8973" velocity="2.175"/>
    <safety_controller k_position="100.0" k_velocity="40.0" soft_lower_limit="-2.8973" soft_upper_limit="2.8973"/>
    <dynamics D="1" K="7000" damping="0.003" friction="0.0" mu_coulomb="0" mu_viscous="16"/>
  </joint>
  <!-- sub-link defining detailed meshes for collision with environment -->
  <link name="arm_1_link2">
    <visual>
      <geometry>
        <mesh filename="package://franka_description/meshes/visual/link2.dae"/>
      </geometry>
    </visual>
    <collision>
      <geometry>
        <mesh filename="package://franka_description/meshes/collision/link2.stl"/>
      </geometry>
    </collision>
  </link>
  <!-- sub-link defining coarse geometries of real robot's internal self-collision -->
  <!-- <link name="${prefix}${name}_sc">
      <xacro:unless value="${gazebo}">
        <xacro:insert_block name="self_collision_geometries" />
      </xacro:unless>
    </link> -->
  <!-- fixed joint between both sub-links -->
  <!-- <joint name="${prefix}${name}_sc_joint" type="fixed">
      <origin rpy="${rpy}" />
      <parent link="${prefix}${name}" />
      <child link="${prefix}${name}_sc" />
    </joint>
     -->
  <!-- Trying to remove the sc joints -->
  <!-- <joint name="${prefix}${name}_sc_joint" type="fixed"> -->
  <!-- <origin rpy="${rpy}" /> -->
  <!-- <parent link="${prefix}${name}" /> -->
  <!-- <child link="${prefix}${name}_sc" /> -->
  <!-- </joint> -->
  <joint name="arm_1_2" type="revolute">
    <origin rpy="-1.5707963267948966 0 0" xyz="0 0 0"/>
    <parent link="arm_1_link1"/>
    <child link="arm_1_link2"/>
    <axis xyz="0 0 1"/>
    <limit effort="87.0" lower="-1.7628" upper="1.7628" velocity="2.175"/>
    <safety_controller k_position="100.0" k_velocity="40.0" soft_lower_limit="-1.7628" soft_upper_limit="1.7628"/>
    <dynamics D="1" K="7000" damping="0.003" friction="0.0" mu_coulomb="0" mu_viscous="16"/>
  </joint>
  <!-- sub-link defining detailed meshes for collision with environment -->
  <link name="arm_1_link3">
    <visual>
      <geometry>
        <mesh filename="package://franka_description/meshes/visual/link3.dae"/>
      </geometry>
    </visual>
    <collision>
      <geometry>
        <mesh filename="package://franka_description/meshes/collision/link3.stl"/>
      </geometry>
    </collision>
  </link>
  <!-- sub-link defining coarse geometries of real robot's internal self-collision -->
  <!-- <link name="${prefix}${name}_sc">
      <xacro:unless value="${gazebo}">
        <xacro:insert_block name="self_collision_geometries" />
      </xacro:unless>
    </link> -->
  <!-- fixed joint between both sub-links -->
  <!-- <joint name="${prefix}${name}_sc_joint" type="fixed">
      <origin rpy="${rpy}" />
      <parent link="${prefix}${name}" />
      <child link="${prefix}${name}_sc" />
    </joint>
     -->
  <!-- Trying to remove the sc joints -->
  <!-- <joint name="${prefix}${name}_sc_joint" type="fixed"> -->
  <!-- <origin rpy="${rpy}" /> -->
  <!-- <parent link="${prefix}${name}" /> -->
  <!-- <child link="${prefix}${name}_sc" /> -->
  <!-- </joint> -->
  <joint name="arm_1_3" type="revolute">
    <origin rpy="1.5707963267948966 0 0" xyz="0 -0.316 0"/>
    <parent link="arm_1_link2"/>
    <child link="arm_1_link3"/>
    <axis xyz="0 0 1"/>
    <limit effort="87.0" lower="-2.8973" upper="2.8973" velocity="2.175"/>
    <safety_controller k_position="100.0" k_velocity="40.0" soft_lower_limit="-2.8973" soft_upper_limit="2.8973"/>
    <dynamics D="1" K="7000" damping="0.003" friction="0.0" mu_coulomb="0" mu_viscous="16"/>
  </joint>
  <!-- sub-link defining detailed meshes for collision with environment -->
  <link name="arm_1_link4">
    <visual>
      <geometry>
        <mesh filename="package://franka_description/meshes/visual/link4.dae"/>
      </geometry>
    </visual>
    <collision>
      <geometry>
        <mesh filename="package://franka_description/meshes/collision/link4.stl"/>
      </geometry>
    </collision>
  </link>
  <!-- sub-link defining coarse geometries of real robot's internal self-collision -->
  <!-- <link name="${prefix}${name}_sc">
      <xacro:unless value="${gazebo}">
        <xacro:insert_block name="self_collision_geometries" />
      </xacro:unless>
    </link> -->
  <!-- fixed joint between both sub-links -->
  <!-- <joint name="${prefix}${name}_sc_joint" type="fixed">
      <origin rpy="${rpy}" />
      <parent link="${prefix}${name}" />
      <child link="${prefix}${name}_sc" />
    </joint>
     -->
  <!-- Trying to remove the sc joints -->
  <!-- <joint name="${prefix}${name}_sc_joint" type="fixed"> -->
  <!-- <origin rpy="${rpy}" /> -->
  <!-- <parent link="${prefix}${name}" /> -->
  <!-- <child link="${prefix}${name}_sc" /> -->
  <!-- </joint> -->
  <joint name="arm_1_4" type="revolute">
    <origin rpy="1.5707963267948966 0 0" xyz="0.0825 0 0"/>
    <parent link="arm_1_link3"/>
    <child link="arm_1_link4"/>
    <axis xyz="0 0 1"/>
    <limit effort="87.0" lower="-3.0718" upper="-0.0698" velocity="2.175"/>
    <safety_controller k_position="100.0" k_velocity="40.0" soft_lower_limit="-3.0718" soft_upper_limit="-0.0698"/>
    <dynamics D="1" K="7000" damping="0.003" friction="0.0" mu_coulomb="0" mu_viscous="16"/>
  </joint>
  <!-- sub-link defining detailed meshes for collision with environment -->
  <link name="arm_1_link5">
    <visual>
      <geometry>
        <mesh filename="package://franka_description/meshes/visual/link5.dae"/>
      </geometry>
    </visual>
    <collision>
      <geometry>
        <mesh filename="package://franka_description/meshes/collision/link5.stl"/>
      </geometry>
    </collision>
  </link>
  <!-- sub-link defining coarse geometries of real robot's internal self-collision -->
  <!-- <link name="${prefix}${name}_sc">
      <xacro:unless value="${gazebo}">
        <xacro:insert_block name="self_collision_geometries" />
      </xacro:unless>
    </link> -->
  <!-- fixed joint between both sub-links -->
  <!-- <joint name="${prefix}${name}_sc_joint" type="fixed">
      <origin rpy="${rpy}" />
      <parent link="${prefix}${name}" />
      <child link="${prefix}${name}_sc" />
    </joint>
     -->
  <!-- Trying to remove the sc joints -->
  <!-- <joint name="${prefix}${name}_sc_joint" type="fixed"> -->
  <!-- <origin rpy="${rpy}" /> -->
  <!-- <parent link="${prefix}${name}" /> -->
  <!-- <child link="${prefix}${name}_sc" /> -->
  <!-- </joint> -->
  <joint name="arm_1_5" type="revolute">
    <origin rpy="-1.5707963267948966 0 0" xyz="-0.0825 0.384 0"/>
    <parent link="arm_1_link4"/>
    <child link="arm_1_link5"/>
    <axis xyz="0 0 1"/>
    <limit effort="12.0" lower="-2.8973" upper="2.8973" velocity="2.61"/>
    <safety_controller k_position="100.0" k_velocity="40.0" soft_lower_limit="-2.8973" soft_upper_limit="2.8973"/>
    <dynamics D="1" K="7000" damping="0.003" friction="0.0" mu_coulomb="0" mu_viscous="16"/>
  </joint>
  <!-- sub-link defining detailed meshes for collision with environment -->
  <link name="arm_1_link6">
    <visual>
      <geometry>
        <mesh filename="package://franka_description/meshes/visual/link6.dae"/>
      </geometry>
    </visual>
    <collision>
      <geometry>
        <mesh filename="package://franka_description/meshes/collision/link6.stl"/>
      </geometry>
    </collision>
  </link>
  <!-- sub-link defining coarse geometries of real robot's internal self-collision -->
  <!-- <link name="${prefix}${name}_sc">
      <xacro:unless value="${gazebo}">
        <xacro:insert_block name="self_collision_geometries" />
      </xacro:unless>
    </link> -->
  <!-- fixed joint between both sub-links -->
  <!-- <joint name="${prefix}${name}_sc_joint" type="fixed">
      <origin rpy="${rpy}" />
      <parent link="${prefix}${name}" />
      <child link="${prefix}${name}_sc" />
    </joint>
     -->
  <!-- Trying to remove the sc joints -->
  <!-- <joint name="${prefix}${name}_sc_joint" type="fixed"> -->
  <!-- <origin rpy="${rpy}" /> -->
  <!-- <parent link="${prefix}${name}" /> -->
  <!-- <child link="${prefix}${name}_sc" /> -->
  <!-- </joint> -->
  <joint name="arm_1_6" type="revolute">
    <origin rpy="1.5707963267948966 0 0" xyz="0 0 0"/>
    <parent link="arm_1_link5"/>
    <child link="arm_1_link6"/>
    <axis xyz="0 0 1"/>
    <limit effort="12.0" lower="-0.0175" upper="3.7525" velocity="2.61"/>
    <safety_controller k_position="100.0" k_velocity="40.0" soft_lower_limit="-0.0175" soft_upper_limit="3.7525"/>
    <dynamics D="1" K="7000" damping="0.003" friction="0.0" mu_coulomb="0" mu_viscous="16"/>
  </joint>
  <!-- sub-link defining detailed meshes for collision with environment -->
  <link name="arm_1_link7">
    <visual>
      <geometry>
        <mesh filename="package://franka_description/meshes/visual/link7.dae"/>
      </geometry>
    </visual>
    <collision>
      <geometry>
        <mesh filename="package://franka_description/meshes/collision/link7.stl"/>
      </geometry>
    </collision>
  </link>
  <!-- sub-link defining coarse geometries of real robot's internal self-collision -->
  <!-- <link name="${prefix}${name}_sc">
      <xacro:unless value="${gazebo}">
        <xacro:insert_block name="self_collision_geometries" />
      </xacro:unless>
    </link> -->
  <!-- fixed joint between both sub-links -->
  <!-- <joint name="${prefix}${name}_sc_joint" type="fixed">
      <origin rpy="${rpy}" />
      <parent link="${prefix}${name}" />
      <child link="${prefix}${name}_sc" />
    </joint>
     -->
  <!-- Trying to remove the sc joints -->
  <!-- <joint name="${prefix}${name}_sc_joint" type="fixed"> -->
  <!-- <origin rpy="${rpy}" /> -->
  <!-- <parent link="${prefix}${name}" /> -->
  <!-- <child link="${prefix}${name}_sc" /> -->
  <!-- </joint> -->
  <joint name="arm_1_7" type="revolute">
    <origin rpy="1.5707963267948966 0 0" xyz="0.088 0 0"/>
    <parent link="arm_1_link6"/>
    <child link="arm_1_link7"/>
    <axis xyz="0 0 1"/>
    <limit effort="12.0" lower="-2.8973" upper="2.8973" velocity="2.61"/>
    <safety_controller k_position="100.0" k_velocity="40.0" soft_lower_limit="-2.8973" soft_upper_limit="2.8973"/>
    <dynamics D="1" K="7000" damping="0.003" friction="0.0" mu_coulomb="0" mu_viscous="16"/>
  </joint>
  <link name="arm_1_link8"/>
  <joint name="arm_1_8" type="fixed">
    <origin rpy="0 0 0" xyz="0 0 0.107"/>
    <parent link="arm_1_link7"/>
    <child link="arm_1_link8"/>
  </joint>
  <joint name="arm_2_joint_shelf_2" type="fixed">
    <parent link="shelf_2"/>
    <child link="arm_2_link0"/>
    <origin rpy="0 0 0" xyz="0 0 0.2"/>
  </joint>
  <!-- sub-link defining detailed meshes for collision with environment -->
  <link name="arm_2_link0">
    <visual>
      <geometry>
        <mesh filename="package://franka_description/meshes/visual/link0.dae"/>
      </geometry>
    </visual>
    <collision>
      <geometry>
        <mesh filename="package://franka_description/meshes/collision/link0.stl"/>
      </geometry>
    </collision>
  </link>
  <!-- sub-link defining coarse geometries of real robot's internal self-collision -->
  <!-- <link name="${prefix}${name}_sc">
      <xacro:unless value="${gazebo}">
        <xacro:insert_block name="self_collision_geometries" />
      </xacro:unless>
    </link> -->
  <!-- fixed joint between both sub-links -->
  <!-- <joint name="${prefix}${name}_sc_joint" type="fixed">
      <origin rpy="${rpy}" />
      <parent link="${prefix}${name}" />
      <child link="${prefix}${name}_sc" />
    </joint>
     -->
  <!-- Trying to remove the sc joints -->
  <!-- <joint name="${prefix}${name}_sc_joint" type="fixed"> -->
  <!-- <origin rpy="${rpy}" /> -->
  <!-- <parent link="${prefix}${name}" /> -->
  <!-- <child link="${prefix}${name}_sc" /> -->
  <!-- </joint> -->
  <!-- sub-link defining detailed meshes for collision with environment -->
  <link name="arm_2_link1">
    <visual>
      <geometry>
        <mesh filename="package://franka_description/meshes/visual/link1.dae"/>
      </geometry>
    </visual>
    <collision>
      <geometry>
        <mesh filename="package://franka_description/meshes/collision/link1.stl"/>
      </geometry>
    </collision>
  </link>
  <!-- sub-link defining coarse geometries of real robot's internal self-collision -->
  <!-- <link name="${prefix}${name}_sc">
      <xacro:unless value="${gazebo}">
        <xacro:insert_block name="self_collision_geometries" />
      </xacro:unless>
    </link> -->
  <!-- fixed joint between both sub-links -->
  <!-- <joint name="${prefix}${name}_sc_joint" type="fixed">
      <origin rpy="${rpy}" />
      <parent link="${prefix}${name}" />
      <child link="${prefix}${name}_sc" />
    </joint>
     -->
  <!-- Trying to remove the sc joints -->
  <!-- <joint name="${prefix}${name}_sc_joint" type="fixed"> -->
  <!-- <origin rpy="${rpy}" /> -->
  <!-- <parent link="${prefix}${name}" /> -->
  <!-- <child link="${prefix}${name}_sc" /> -->
  <!-- </joint> -->
  <joint name="arm_2_1" type="revolute">
    <origin rpy="0 0 0" xyz="0 0 0.333"/>
    <parent link="arm_2_link0"/>
    <child link="arm_2_link1"/>
    <axis xyz="0 0 1"/>
    <limit effort="87.0" lower="-2.8973" upper="2.8973" velocity="2.175"/>
    <safety_controller k_position="100.0" k_velocity="40.0" soft_lower_limit="-2.8973" soft_upper_limit="2.8973"/>
    <dynamics D="1" K="7000" damping="0.003" friction="0.0" mu_coulomb="0" mu_viscous="16"/>
  </joint>
  <!-- sub-link defining detailed meshes for collision with environment -->
  <link name="arm_2_link2">
    <visual>
      <geometry>
        <mesh filename="package://franka_description/meshes/visual/link2.dae"/>
      </geometry>
    </visual>
    <collision>
      <geometry>
        <mesh filename="package://franka_description/meshes/collision/link2.stl"/>
      </geometry>
    </collision>
  </link>
  <!-- sub-link defining coarse geometries of real robot's internal self-collision -->
  <!-- <link name="${prefix}${name}_sc">
      <xacro:unless value="${gazebo}">
        <xacro:insert_block name="self_collision_geometries" />
      </xacro:unless>
    </link> -->
  <!-- fixed joint between both sub-links -->
  <!-- <joint name="${prefix}${name}_sc_joint" type="fixed">
      <origin rpy="${rpy}" />
      <parent link="${prefix}${name}" />
      <child link="${prefix}${name}_sc" />
    </joint>
     -->
  <!-- Trying to remove the sc joints -->
  <!-- <joint name="${prefix}${name}_sc_joint" type="fixed"> -->
  <!-- <origin rpy="${rpy}" /> -->
  <!-- <parent link="${prefix}${name}" /> -->
  <!-- <child link="${prefix}${name}_sc" /> -->
  <!-- </joint> -->
  <joint name="arm_2_2" type="revolute">
    <origin rpy="-1.5707963267948966 0 0" xyz="0 0 0"/>
    <parent link="arm_2_link1"/>
    <child link="arm_2_link2"/>
    <axis xyz="0 0 1"/>
    <limit effort="87.0" lower="-1.7628" upper="1.7628" velocity="2.175"/>
    <safety_controller k_position="100.0" k_velocity="40.0" soft_lower_limit="-1.7628" soft_upper_limit="1.7628"/>
    <dynamics D="1" K="7000" damping="0.003" friction="0.0" mu_coulomb="0" mu_viscous="16"/>
  </joint>
  <!-- sub-link defining detailed meshes for collision with environment -->
  <link name="arm_2_link3">
    <visual>
      <geometry>
        <mesh filename="package://franka_description/meshes/visual/link3.dae"/>
      </geometry>
    </visual>
    <collision>
      <geometry>
        <mesh filename="package://franka_description/meshes/collision/link3.stl"/>
      </geometry>
    </collision>
  </link>
  <!-- sub-link defining coarse geometries of real robot's internal self-collision -->
  <!-- <link name="${prefix}${name}_sc">
      <xacro:unless value="${gazebo}">
        <xacro:insert_block name="self_collision_geometries" />
      </xacro:unless>
    </link> -->
  <!-- fixed joint between both sub-links -->
  <!-- <joint name="${prefix}${name}_sc_joint" type="fixed">
      <origin rpy="${rpy}" />
      <parent link="${prefix}${name}" />
      <child link="${prefix}${name}_sc" />
    </joint>
     -->
  <!-- Trying to remove the sc joints -->
  <!-- <joint name="${prefix}${name}_sc_joint" type="fixed"> -->
  <!-- <origin rpy="${rpy}" /> -->
  <!-- <parent link="${prefix}${name}" /> -->
  <!-- <child link="${prefix}${name}_sc" /> -->
  <!-- </joint> -->
  <joint name="arm_2_3" type="revolute">
    <origin rpy="1.5707963267948966 0 0" xyz="0 -0.316 0"/>
    <parent link="arm_2_link2"/>
    <child link="arm_2_link3"/>
    <axis xyz="0 0 1"/>
    <limit effort="87.0" lower="-2.8973" upper="2.8973" velocity="2.175"/>
    <safety_controller k_position="100.0" k_velocity="40.0" soft_lower_limit="-2.8973" soft_upper_limit="2.8973"/>
    <dynamics D="1" K="7000" damping="0.003" friction="0.0" mu_coulomb="0" mu_viscous="16"/>
  </joint>
  <!-- sub-link defining detailed meshes for collision with environment -->
  <link name="arm_2_link4">
    <visual>
      <geometry>
        <mesh filename="package://franka_description/meshes/visual/link4.dae"/>
      </geometry>
    </visual>
    <collision>
      <geometry>
        <mesh filename="package://franka_description/meshes/collision/link4.stl"/>
      </geometry>
    </collision>
  </link>
  <!-- sub-link defining coarse geometries of real robot's internal self-collision -->
  <!-- <link name="${prefix}${name}_sc">
      <xacro:unless value="${gazebo}">
        <xacro:insert_block name="self_collision_geometries" />
      </xacro:unless>
    </link> -->
  <!-- fixed joint between both sub-links -->
  <!-- <joint name="${prefix}${name}_sc_joint" type="fixed">
      <origin rpy="${rpy}" />
      <parent link="${prefix}${name}" />
      <child link="${prefix}${name}_sc" />
    </joint>
     -->
  <!-- Trying to remove the sc joints -->
  <!-- <joint name="${prefix}${name}_sc_joint" type="fixed"> -->
  <!-- <origin rpy="${rpy}" /> -->
  <!-- <parent link="${prefix}${name}" /> -->
  <!-- <child link="${prefix}${name}_sc" /> -->
  <!-- </joint> -->
  <joint name="arm_2_4" type="revolute">
    <origin rpy="1.5707963267948966 0 0" xyz="0.0825 0 0"/>
    <parent link="arm_2_link3"/>
    <child link="arm_2_link4"/>
    <axis xyz="0 0 1"/>
    <limit effort="87.0" lower="-3.0718" upper="-0.0698" velocity="2.175"/>
    <safety_controller k_position="100.0" k_velocity="40.0" soft_lower_limit="-3.0718" soft_upper_limit="-0.0698"/>
    <dynamics D="1" K="7000" damping="0.003" friction="0.0" mu_coulomb="0" mu_viscous="16"/>
  </joint>
  <!-- sub-link defining detailed meshes for collision with environment -->
  <link name="arm_2_link5">
    <visual>
      <geometry>
        <mesh filename="package://franka_description/meshes/visual/link5.dae"/>
      </geometry>
    </visual>
    <collision>
      <geometry>
        <mesh filename="package://franka_description/meshes/collision/link5.stl"/>
      </geometry>
    </collision>
  </link>
  <!-- sub-link defining coarse geometries of real robot's internal self-collision -->
  <!-- <link name="${prefix}${name}_sc">
      <xacro:unless value="${gazebo}">
        <xacro:insert_block name="self_collision_geometries" />
      </xacro:unless>
    </link> -->
  <!-- fixed joint between both sub-links -->
  <!-- <joint name="${prefix}${name}_sc_joint" type="fixed">
      <origin rpy="${rpy}" />
      <parent link="${prefix}${name}" />
      <child link="${prefix}${name}_sc" />
    </joint>
     -->
  <!-- Trying to remove the sc joints -->
  <!-- <joint name="${prefix}${name}_sc_joint" type="fixed"> -->
  <!-- <origin rpy="${rpy}" /> -->
  <!-- <parent link="${prefix}${name}" /> -->
  <!-- <child link="${prefix}${name}_sc" /> -->
  <!-- </joint> -->
  <joint name="arm_2_5" type="revolute">
    <origin rpy="-1.5707963267948966 0 0" xyz="-0.0825 0.384 0"/>
    <parent link="arm_2_link4"/>
    <child link="arm_2_link5"/>
    <axis xyz="0 0 1"/>
    <limit effort="12.0" lower="-2.8973" upper="2.8973" velocity="2.61"/>
    <safety_controller k_position="100.0" k_velocity="40.0" soft_lower_limit="-2.8973" soft_upper_limit="2.8973"/>
    <dynamics D="1" K="7000" damping="0.003" friction="0.0" mu_coulomb="0" mu_viscous="16"/>
  </joint>
  <!-- sub-link defining detailed meshes for collision with environment -->
  <link name="arm_2_link6">
    <visual>
      <geometry>
        <mesh filename="package://franka_description/meshes/visual/link6.dae"/>
      </geometry>
    </visual>
    <collision>
      <geometry>
        <mesh filename="package://franka_description/meshes/collision/link6.stl"/>
      </geometry>
    </collision>
  </link>
  <!-- sub-link defining coarse geometries of real robot's internal self-collision -->
  <!-- <link name="${prefix}${name}_sc">
      <xacro:unless value="${gazebo}">
        <xacro:insert_block name="self_collision_geometries" />
      </xacro:unless>
    </link> -->
  <!-- fixed joint between both sub-links -->
  <!-- <joint name="${prefix}${name}_sc_joint" type="fixed">
      <origin rpy="${rpy}" />
      <parent link="${prefix}${name}" />
      <child link="${prefix}${name}_sc" />
    </joint>
     -->
  <!-- Trying to remove the sc joints -->
  <!-- <joint name="${prefix}${name}_sc_joint" type="fixed"> -->
  <!-- <origin rpy="${rpy}" /> -->
  <!-- <parent link="${prefix}${name}" /> -->
  <!-- <child link="${prefix}${name}_sc" /> -->
  <!-- </joint> -->
  <joint name="arm_2_6" type="revolute">
    <origin rpy="1.5707963267948966 0 0" xyz="0 0 0"/>
    <parent link="arm_2_link5"/>
    <child link="arm_2_link6"/>
    <axis xyz="0 0 1"/>
    <limit effort="12.0" lower="-0.0175" upper="3.7525" velocity="2.61"/>
    <safety_controller k_position="100.0" k_velocity="40.0" soft_lower_limit="-0.0175" soft_upper_limit="3.7525"/>
    <dynamics D="1" K="7000" damping="0.003" friction="0.0" mu_coulomb="0" mu_viscous="16"/>
  </joint>
  <!-- sub-link defining detailed meshes for collision with environment -->
  <link name="arm_2_link7">
    <visual>
      <geometry>
        <mesh filename="package://franka_description/meshes/visual/link7.dae"/>
      </geometry>
    </visual>
    <collision>
      <geometry>
        <mesh filename="package://franka_description/meshes/collision/link7.stl"/>
      </geometry>
    </collision>
  </link>
  <!-- sub-link defining coarse geometries of real robot's internal self-collision -->
  <!-- <link name="${prefix}${name}_sc">
      <xacro:unless value="${gazebo}">
        <xacro:insert_block name="self_collision_geometries" />
      </xacro:unless>
    </link> -->
  <!-- fixed joint between both sub-links -->
  <!-- <joint name="${prefix}${name}_sc_joint" type="fixed">
      <origin rpy="${rpy}" />
      <parent link="${prefix}${name}" />
      <child link="${prefix}${name}_sc" />
    </joint>
     -->
  <!-- Trying to remove the sc joints -->
  <!-- <joint name="${prefix}${name}_sc_joint" type="fixed"> -->
  <!-- <origin rpy="${rpy}" /> -->
  <!-- <parent link="${prefix}${name}" /> -->
  <!-- <child link="${prefix}${name}_sc" /> -->
  <!-- </joint> -->
  <joint name="arm_2_7" type="revolute">
    <origin rpy="1.5707963267948966 0 0" xyz="0.088 0 0"/>
    <parent link="arm_2_link6"/>
    <child link="arm_2_link7"/>
    <axis xyz="0 0 1"/>
    <limit effort="12.0" lower="-2.8973" upper="2.8973" velocity="2.61"/>
    <safety_controller k_position="100.0" k_velocity="40.0" soft_lower_limit="-2.8973" soft_upper_limit="2.8973"/>
    <dynamics D="1" K="7000" damping="0.003" friction="0.0" mu_coulomb="0" mu_viscous="16"/>
  </joint>
  <link name="arm_2_link8"/>
  <joint name="arm_2_8" type="fixed">
    <origin rpy="0 0 0" xyz="0 0 0.107"/>
    <parent link="arm_2_link7"/>
    <child link="arm_2_link8"/>
  </joint>
  <joint name="arm_3_joint_shelf_3" type="fixed">
    <parent link="shelf_3"/>
    <child link="arm_3_link0"/>
    <origin rpy="0 0 0" xyz="0 0 0.2"/>
  </joint>
  <!-- sub-link defining detailed meshes for collision with environment -->
  <link name="arm_3_link0">
    <visual>
      <geometry>
        <mesh filename="package://franka_description/meshes/visual/link0.dae"/>
      </geometry>
    </visual>
    <collision>
      <geometry>
        <mesh filename="package://franka_description/meshes/collision/link0.stl"/>
      </geometry>
    </collision>
  </link>
  <!-- sub-link defining coarse geometries of real robot's internal self-collision -->
  <!-- <link name="${prefix}${name}_sc">
      <xacro:unless value="${gazebo}">
        <xacro:insert_block name="self_collision_geometries" />
      </xacro:unless>
    </link> -->
  <!-- fixed joint between both sub-links -->
  <!-- <joint name="${prefix}${name}_sc_joint" type="fixed">
      <origin rpy="${rpy}" />
      <parent link="${prefix}${name}" />
      <child link="${prefix}${name}_sc" />
    </joint>
     -->
  <!-- Trying to remove the sc joints -->
  <!-- <joint name="${prefix}${name}_sc_joint" type="fixed"> -->
  <!-- <origin rpy="${rpy}" /> -->
  <!-- <parent link="${prefix}${name}" /> -->
  <!-- <child link="${prefix}${name}_sc" /> -->
  <!-- </joint> -->
  <!-- sub-link defining detailed meshes for collision with environment -->
  <link name="arm_3_link1">
    <visual>
      <geometry>
        <mesh filename="package://franka_description/meshes/visual/link1.dae"/>
      </geometry>
    </visual>
    <collision>
      <geometry>
        <mesh filename="package://franka_description/meshes/collision/link1.stl"/>
      </geometry>
    </collision>
  </link>
  <!-- sub-link defining coarse geometries of real robot's internal self-collision -->
  <!-- <link name="${prefix}${name}_sc">
      <xacro:unless value="${gazebo}">
        <xacro:insert_block name="self_collision_geometries" />
      </xacro:unless>
    </link> -->
  <!-- fixed joint between both sub-links -->
  <!-- <joint name="${prefix}${name}_sc_joint" type="fixed">
      <origin rpy="${rpy}" />
      <parent link="${prefix}${name}" />
      <child link="${prefix}${name}_sc" />
    </joint>
     -->
  <!-- Trying to remove the sc joints -->
  <!-- <joint name="${prefix}${name}_sc_joint" type="fixed"> -->
  <!-- <origin rpy="${rpy}" /> -->
  <!-- <parent link="${prefix}${name}" /> -->
  <!-- <child link="${prefix}${name}_sc" /> -->
  <!-- </joint> -->
  <joint name="arm_3_1" type="revolute">
    <origin rpy="0 0 0" xyz="0 0 0.333"/>
    <parent link="arm_3_link0"/>
    <child link="arm_3_link1"/>
    <axis xyz="0 0 1"/>
    <limit effort="87.0" lower="-2.8973" upper="2.8973" velocity="2.175"/>
    <safety_controller k_position="100.0" k_velocity="40.0" soft_lower_limit="-2.8973" soft_upper_limit="2.8973"/>
    <dynamics D="1" K="7000" damping="0.003" friction="0.0" mu_coulomb="0" mu_viscous="16"/>
  </joint>
  <!-- sub-link defining detailed meshes for collision with environment -->
  <link name="arm_3_link2">
    <visual>
      <geometry>
        <mesh filename="package://franka_description/meshes/visual/link2.dae"/>
      </geometry>
    </visual>
    <collision>
      <geometry>
        <mesh filename="package://franka_description/meshes/collision/link2.stl"/>
      </geometry>
    </collision>
  </link>
  <!-- sub-link defining coarse geometries of real robot's internal self-collision -->
  <!-- <link name="${prefix}${name}_sc">
      <xacro:unless value="${gazebo}">
        <xacro:insert_block name="self_collision_geometries" />
      </xacro:unless>
    </link> -->
  <!-- fixed joint between both sub-links -->
  <!-- <joint name="${prefix}${name}_sc_joint" type="fixed">
      <origin rpy="${rpy}" />
      <parent link="${prefix}${name}" />
      <child link="${prefix}${name}_sc" />
    </joint>
     -->
  <!-- Trying to remove the sc joints -->
  <!-- <joint name="${prefix}${name}_sc_joint" type="fixed"> -->
  <!-- <origin rpy="${rpy}" /> -->
  <!-- <parent link="${prefix}${name}" /> -->
  <!-- <child link="${prefix}${name}_sc" /> -->
  <!-- </joint> -->
  <joint name="arm_3_2" type="revolute">
    <origin rpy="-1.5707963267948966 0 0" xyz="0 0 0"/>
    <parent link="arm_3_link1"/>
    <child link="arm_3_link2"/>
    <axis xyz="0 0 1"/>
    <limit effort="87.0" lower="-1.7628" upper="1.7628" velocity="2.175"/>
    <safety_controller k_position="100.0" k_velocity="40.0" soft_lower_limit="-1.7628" soft_upper_limit="1.7628"/>
    <dynamics D="1" K="7000" damping="0.003" friction="0.0" mu_coulomb="0" mu_viscous="16"/>
  </joint>
  <!-- sub-link defining detailed meshes for collision with environment -->
  <link name="arm_3_link3">
    <visual>
      <geometry>
        <mesh filename="package://franka_description/meshes/visual/link3.dae"/>
      </geometry>
    </visual>
    <collision>
      <geometry>
        <mesh filename="package://franka_description/meshes/collision/link3.stl"/>
      </geometry>
    </collision>
  </link>
  <!-- sub-link defining coarse geometries of real robot's internal self-collision -->
  <!-- <link name="${prefix}${name}_sc">
      <xacro:unless value="${gazebo}">
        <xacro:insert_block name="self_collision_geometries" />
      </xacro:unless>
    </link> -->
  <!-- fixed joint between both sub-links -->
  <!-- <joint name="${prefix}${name}_sc_joint" type="fixed">
      <origin rpy="${rpy}" />
      <parent link="${prefix}${name}" />
      <child link="${prefix}${name}_sc" />
    </joint>
     -->
  <!-- Trying to remove the sc joints -->
  <!-- <joint name="${prefix}${name}_sc_joint" type="fixed"> -->
  <!-- <origin rpy="${rpy}" /> -->
  <!-- <parent link="${prefix}${name}" /> -->
  <!-- <child link="${prefix}${name}_sc" /> -->
  <!-- </joint> -->
  <joint name="arm_3_3" type="revolute">
    <origin rpy="1.5707963267948966 0 0" xyz="0 -0.316 0"/>
    <parent link="arm_3_link2"/>
    <child link="arm_3_link3"/>
    <axis xyz="0 0 1"/>
    <limit effort="87.0" lower="-2.8973" upper="2.8973" velocity="2.175"/>
    <safety_controller k_position="100.0" k_velocity="40.0" soft_lower_limit="-2.8973" soft_upper_limit="2.8973"/>
    <dynamics D="1" K="7000" damping="0.003" friction="0.0" mu_coulomb="0" mu_viscous="16"/>
  </joint>
  <!-- sub-link defining detailed meshes for collision with environment -->
  <link name="arm_3_link4">
    <visual>
      <geometry>
        <mesh filename="package://franka_description/meshes/visual/link4.dae"/>
      </geometry>
    </visual>
    <collision>
      <geometry>
        <mesh filename="package://franka_description/meshes/collision/link4.stl"/>
      </geometry>
    </collision>
  </link>
  <!-- sub-link defining coarse geometries of real robot's internal self-collision -->
  <!-- <link name="${prefix}${name}_sc">
      <xacro:unless value="${gazebo}">
        <xacro:insert_block name="self_collision_geometries" />
      </xacro:unless>
    </link> -->
  <!-- fixed joint between both sub-links -->
  <!-- <joint name="${prefix}${name}_sc_joint" type="fixed">
      <origin rpy="${rpy}" />
      <parent link="${prefix}${name}" />
      <child link="${prefix}${name}_sc" />
    </joint>
     -->
  <!-- Trying to remove the sc joints -->
  <!-- <joint name="${prefix}${name}_sc_joint" type="fixed"> -->
  <!-- <origin rpy="${rpy}" /> -->
  <!-- <parent link="${prefix}${name}" /> -->
  <!-- <child link="${prefix}${name}_sc" /> -->
  <!-- </joint> -->
  <joint name="arm_3_4" type="revolute">
    <origin rpy="1.5707963267948966 0 0" xyz="0.0825 0 0"/>
    <parent link="arm_3_link3"/>
    <child link="arm_3_link4"/>
    <axis xyz="0 0 1"/>
    <limit effort="87.0" lower="-3.0718" upper="-0.0698" velocity="2.175"/>
    <safety_controller k_position="100.0" k_velocity="40.0" soft_lower_limit="-3.0718" soft_upper_limit="-0.0698"/>
    <dynamics D="1" K="7000" damping="0.003" friction="0.0" mu_coulomb="0" mu_viscous="16"/>
  </joint>
  <!-- sub-link defining detailed meshes for collision with environment -->
  <link name="arm_3_link5">
    <visual>
      <geometry>
        <mesh filename="package://franka_description/meshes/visual/link5.dae"/>
      </geometry>
    </visual>
    <collision>
      <geometry>
        <mesh filename="package://franka_description/meshes/collision/link5.stl"/>
      </geometry>
    </collision>
  </link>
  <!-- sub-link defining coarse geometries of real robot's internal self-collision -->
  <!-- <link name="${prefix}${name}_sc">
      <xacro:unless value="${gazebo}">
        <xacro:insert_block name="self_collision_geometries" />
      </xacro:unless>
    </link> -->
  <!-- fixed joint between both sub-links -->
  <!-- <joint name="${prefix}${name}_sc_joint" type="fixed">
      <origin rpy="${rpy}" />
      <parent link="${prefix}${name}" />
      <child link="${prefix}${name}_sc" />
    </joint>
     -->
  <!-- Trying to remove the sc joints -->
  <!-- <joint name="${prefix}${name}_sc_joint" type="fixed"> -->
  <!-- <origin rpy="${rpy}" /> -->
  <!-- <parent link="${prefix}${name}" /> -->
  <!-- <child link="${prefix}${name}_sc" /> -->
  <!-- </joint> -->
  <joint name="arm_3_5" type="revolute">
    <origin rpy="-1.5707963267948966 0 0" xyz="-0.0825 0.384 0"/>
    <parent link="arm_3_link4"/>
    <child link="arm_3_link5"/>
    <axis xyz="0 0 1"/>
    <limit effort="12.0" lower="-2.8973" upper="2.8973" velocity="2.61"/>
    <safety_controller k_position="100.0" k_velocity="40.0" soft_lower_limit="-2.8973" soft_upper_limit="2.8973"/>
    <dynamics D="1" K="7000" damping="0.003" friction="0.0" mu_coulomb="0" mu_viscous="16"/>
  </joint>
  <!-- sub-link defining detailed meshes for collision with environment -->
  <link name="arm_3_link6">
    <visual>
      <geometry>
        <mesh filename="package://franka_description/meshes/visual/link6.dae"/>
      </geometry>
    </visual>
    <collision>
      <geometry>
        <mesh filename="package://franka_description/meshes/collision/link6.stl"/>
      </geometry>
    </collision>
  </link>
  <!-- sub-link defining coarse geometries of real robot's internal self-collision -->
  <!-- <link name="${prefix}${name}_sc">
      <xacro:unless value="${gazebo}">
        <xacro:insert_block name="self_collision_geometries" />
      </xacro:unless>
    </link> -->
  <!-- fixed joint between both sub-links -->
  <!-- <joint name="${prefix}${name}_sc_joint" type="fixed">
      <origin rpy="${rpy}" />
      <parent link="${prefix}${name}" />
      <child link="${prefix}${name}_sc" />
    </joint>
     -->
  <!-- Trying to remove the sc joints -->
  <!-- <joint name="${prefix}${name}_sc_joint" type="fixed"> -->
  <!-- <origin rpy="${rpy}" /> -->
  <!-- <parent link="${prefix}${name}" /> -->
  <!-- <child link="${prefix}${name}_sc" /> -->
  <!-- </joint> -->
  <joint name="arm_3_6" type="revolute">
    <origin rpy="1.5707963267948966 0 0" xyz="0 0 0"/>
    <parent link="arm_3_link5"/>
    <child link="arm_3_link6"/>
    <axis xyz="0 0 1"/>
    <limit effort="12.0" lower="-0.0175" upper="3.7525" velocity="2.61"/>
    <safety_controller k_position="100.0" k_velocity="40.0" soft_lower_limit="-0.0175" soft_upper_limit="3.7525"/>
    <dynamics D="1" K="7000" damping="0.003" friction="0.0" mu_coulomb="0" mu_viscous="16"/>
  </joint>
  <!-- sub-link defining detailed meshes for collision with environment -->
  <link name="arm_3_link7">
    <visual>
      <geometry>
        <mesh filename="package://franka_description/meshes/visual/link7.dae"/>
      </geometry>
    </visual>
    <collision>
      <geometry>
        <mesh filename="package://franka_description/meshes/collision/link7.stl"/>
      </geometry>
    </collision>
  </link>
  <!-- sub-link defining coarse geometries of real robot's internal self-collision -->
  <!-- <link name="${prefix}${name}_sc">
      <xacro:unless value="${gazebo}">
        <xacro:insert_block name="self_collision_geometries" />
      </xacro:unless>
    </link> -->
  <!-- fixed joint between both sub-links -->
  <!-- <joint name="${prefix}${name}_sc_joint" type="fixed">
      <origin rpy="${rpy}" />
      <parent link="${prefix}${name}" />
      <child link="${prefix}${name}_sc" />
    </joint>
     -->
  <!-- Trying to remove the sc joints -->
  <!-- <joint name="${prefix}${name}_sc_joint" type="fixed"> -->
  <!-- <origin rpy="${rpy}" /> -->
  <!-- <parent link="${prefix}${name}" /> -->
  <!-- <child link="${prefix}${name}_sc" /> -->
  <!-- </joint> -->
  <joint name="arm_3_7" type="revolute">
    <origin rpy="1.5707963267948966 0 0" xyz="0.088 0 0"/>
    <parent link="arm_3_link6"/>
    <child link="arm_3_link7"/>
    <axis xyz="0 0 1"/>
    <limit effort="12.0" lower="-2.8973" upper="2.8973" velocity="2.61"/>
    <safety_controller k_position="100.0" k_velocity="40.0" soft_lower_limit="-2.8973" soft_upper_limit="2.8973"/>
    <dynamics D="1" K="7000" damping="0.003" friction="0.0" mu_coulomb="0" mu_viscous="16"/>
  </joint>
  <link name="arm_3_link8"/>
  <joint name="arm_3_8" type="fixed">
    <origin rpy="0 0 0" xyz="0 0 0.107"/>
    <parent link="arm_3_link7"/>
    <child link="arm_3_link8"/>
  </joint>
  <joint name="arm_4_joint_shelf_4" type="fixed">
    <parent link="shelf_4"/>
    <child link="arm_4_link0"/>
    <origin rpy="0 0 0" xyz="0 0 0.2"/>
  </joint>
  <!-- sub-link defining detailed meshes for collision with environment -->
  <link name="arm_4_link0">
    <visual>
      <geometry>
        <mesh filename="package://franka_description/meshes/visual/link0.dae"/>
      </geometry>
    </visual>
    <collision>
      <geometry>
        <mesh filename="package://franka_description/meshes/collision/link0.stl"/>
      </geometry>
    </collision>
  </link>
  <!-- sub-link defining coarse geometries of real robot's internal self-collision -->
  <!-- <link name="${prefix}${name}_sc">
      <xacro:unless value="${gazebo}">
        <xacro:insert_block name="self_collision_geometries" />
      </xacro:unless>
    </link> -->
  <!-- fixed joint between both sub-links -->
  <!-- <joint name="${prefix}${name}_sc_joint" type="fixed">
      <origin rpy="${rpy}" />
      <parent link="${prefix}${name}" />
      <child link="${prefix}${name}_sc" />
    </joint>
     -->
  <!-- Trying to remove the sc joints -->
  <!-- <joint name="${prefix}${name}_sc_joint" type="fixed"> -->
  <!-- <origin rpy="${rpy}" /> -->
  <!-- <parent link="${prefix}${name}" /> -->
  <!-- <child link="${prefix}${name}_sc" /> -->
  <!-- </joint> -->
  <!-- sub-link defining detailed meshes for collision with environment -->
  <link name="arm_4_link1">
    <visual>
      <geometry>
        <mesh filename="package://franka_description/meshes/visual/link1.dae"/>
      </geometry>
    </visual>
    <collision>
      <geometry>
        <mesh filename="package://franka_description/meshes/collision/link1.stl"/>
      </geometry>
    </collision>
  </link>
  <!-- sub-link defining coarse geometries of real robot's internal self-collision -->
  <!-- <link name="${prefix}${name}_sc">
      <xacro:unless value="${gazebo}">
        <xacro:insert_block name="self_collision_geometries" />
      </xacro:unless>
    </link> -->
  <!-- fixed joint between both sub-links -->
  <!-- <joint name="${prefix}${name}_sc_joint" type="fixed">
      <origin rpy="${rpy}" />
      <parent link="${prefix}${name}" />
      <child link="${prefix}${name}_sc" />
    </joint>
     -->
  <!-- Trying to remove the sc joints -->
  <!-- <joint name="${prefix}${name}_sc_joint" type="fixed"> -->
  <!-- <origin rpy="${rpy}" /> -->
  <!-- <parent link="${prefix}${name}" /> -->
  <!-- <child link="${prefix}${name}_sc" /> -->
  <!-- </joint> -->
  <joint name="arm_4_1" type="revolute">
    <origin rpy="0 0 0" xyz="0 0 0.333"/>
    <parent link="arm_4_link0"/>
    <child link="arm_4_link1"/>
    <axis xyz="0 0 1"/>
    <limit effort="87.0" lower="-2.8973" upper="2.8973" velocity="2.175"/>
    <safety_controller k_position="100.0" k_velocity="40.0" soft_lower_limit="-2.8973" soft_upper_limit="2.8973"/>
    <dynamics D="1" K="7000" damping="0.003" friction="0.0" mu_coulomb="0" mu_viscous="16"/>
  </joint>
  <!-- sub-link defining detailed meshes for collision with environment -->
  <link name="arm_4_link2">
    <visual>
      <geometry>
        <mesh filename="package://franka_description/meshes/visual/link2.dae"/>
      </geometry>
    </visual>
    <collision>
      <geometry>
        <mesh filename="package://franka_description/meshes/collision/link2.stl"/>
      </geometry>
    </collision>
  </link>
  <!-- sub-link defining coarse geometries of real robot's internal self-collision -->
  <!-- <link name="${prefix}${name}_sc">
      <xacro:unless value="${gazebo}">
        <xacro:insert_block name="self_collision_geometries" />
      </xacro:unless>
    </link> -->
  <!-- fixed joint between both sub-links -->
  <!-- <joint name="${prefix}${name}_sc_joint" type="fixed">
      <origin rpy="${rpy}" />
      <parent link="${prefix}${name}" />
      <child link="${prefix}${name}_sc" />
    </joint>
     -->
  <!-- Trying to remove the sc joints -->
  <!-- <joint name="${prefix}${name}_sc_joint" type="fixed"> -->
  <!-- <origin rpy="${rpy}" /> -->
  <!-- <parent link="${prefix}${name}" /> -->
  <!-- <child link="${prefix}${name}_sc" /> -->
  <!-- </joint> -->
  <joint name="arm_4_2" type="revolute">
    <origin rpy="-1.5707963267948966 0 0" xyz="0 0 0"/>
    <parent link="arm_4_link1"/>
    <child link="arm_4_link2"/>
    <axis xyz="0 0 1"/>
    <limit effort="87.0" lower="-1.7628" upper="1.7628" velocity="2.175"/>
    <safety_controller k_position="100.0" k_velocity="40.0" soft_lower_limit="-1.7628" soft_upper_limit="1.7628"/>
    <dynamics D="1" K="7000" damping="0.003" friction="0.0" mu_coulomb="0" mu_viscous="16"/>
  </joint>
  <!-- sub-link defining detailed meshes for collision with environment -->
  <link name="arm_4_link3">
    <visual>
      <geometry>
        <mesh filename="package://franka_description/meshes/visual/link3.dae"/>
      </geometry>
    </visual>
    <collision>
      <geometry>
        <mesh filename="package://franka_description/meshes/collision/link3.stl"/>
      </geometry>
    </collision>
  </link>
  <!-- sub-link defining coarse geometries of real robot's internal self-collision -->
  <!-- <link name="${prefix}${name}_sc">
      <xacro:unless value="${gazebo}">
        <xacro:insert_block name="self_collision_geometries" />
      </xacro:unless>
    </link> -->
  <!-- fixed joint between both sub-links -->
  <!-- <joint name="${prefix}${name}_sc_joint" type="fixed">
      <origin rpy="${rpy}" />
      <parent link="${prefix}${name}" />
      <child link="${prefix}${name}_sc" />
    </joint>
     -->
  <!-- Trying to remove the sc joints -->
  <!-- <joint name="${prefix}${name}_sc_joint" type="fixed"> -->
  <!-- <origin rpy="${rpy}" /> -->
  <!-- <parent link="${prefix}${name}" /> -->
  <!-- <child link="${prefix}${name}_sc" /> -->
  <!-- </joint> -->
  <joint name="arm_4_3" type="revolute">
    <origin rpy="1.5707963267948966 0 0" xyz="0 -0.316 0"/>
    <parent link="arm_4_link2"/>
    <child link="arm_4_link3"/>
    <axis xyz="0 0 1"/>
    <limit effort="87.0" lower="-2.8973" upper="2.8973" velocity="2.175"/>
    <safety_controller k_position="100.0" k_velocity="40.0" soft_lower_limit="-2.8973" soft_upper_limit="2.8973"/>
    <dynamics D="1" K="7000" damping="0.003" friction="0.0" mu_coulomb="0" mu_viscous="16"/>
  </joint>
  <!-- sub-link defining detailed meshes for collision with environment -->
  <link name="arm_4_link4">
    <visual>
      <geometry>
        <mesh filename="package://franka_description/meshes/visual/link4.dae"/>
      </geometry>
    </visual>
    <collision>
      <geometry>
        <mesh filename="package://franka_description/meshes/collision/link4.stl"/>
      </geometry>
    </collision>
  </link>
  <!-- sub-link defining coarse geometries of real robot's internal self-collision -->
  <!-- <link name="${prefix}${name}_sc">
      <xacro:unless value="${gazebo}">
        <xacro:insert_block name="self_collision_geometries" />
      </xacro:unless>
    </link> -->
  <!-- fixed joint between both sub-links -->
  <!-- <joint name="${prefix}${name}_sc_joint" type="fixed">
      <origin rpy="${rpy}" />
      <parent link="${prefix}${name}" />
      <child link="${prefix}${name}_sc" />
    </joint>
     -->
  <!-- Trying to remove the sc joints -->
  <!-- <joint name="${prefix}${name}_sc_joint" type="fixed"> -->
  <!-- <origin rpy="${rpy}" /> -->
  <!-- <parent link="${prefix}${name}" /> -->
  <!-- <child link="${prefix}${name}_sc" /> -->
  <!-- </joint> -->
  <joint name="arm_4_4" type="revolute">
    <origin rpy="1.5707963267948966 0 0" xyz="0.0825 0 0"/>
    <parent link="arm_4_link3"/>
    <child link="arm_4_link4"/>
    <axis xyz="0 0 1"/>
    <limit effort="87.0" lower="-3.0718" upper="-0.0698" velocity="2.175"/>
    <safety_controller k_position="100.0" k_velocity="40.0" soft_lower_limit="-3.0718" soft_upper_limit="-0.0698"/>
    <dynamics D="1" K="7000" damping="0.003" friction="0.0" mu_coulomb="0" mu_viscous="16"/>
  </joint>
  <!-- sub-link defining detailed meshes for collision with environment -->
  <link name="arm_4_link5">
    <visual>
      <geometry>
        <mesh filename="package://franka_description/meshes/visual/link5.dae"/>
      </geometry>
    </visual>
    <collision>
      <geometry>
        <mesh filename="package://franka_description/meshes/collision/link5.stl"/>
      </geometry>
    </collision>
  </link>
  <!-- sub-link defining coarse geometries of real robot's internal self-collision -->
  <!-- <link name="${prefix}${name}_sc">
      <xacro:unless value="${gazebo}">
        <xacro:insert_block name="self_collision_geometries" />
      </xacro:unless>
    </link> -->
  <!-- fixed joint between both sub-links -->
  <!-- <joint name="${prefix}${name}_sc_joint" type="fixed">
      <origin rpy="${rpy}" />
      <parent link="${prefix}${name}" />
      <child link="${prefix}${name}_sc" />
    </joint>
     -->
  <!-- Trying to remove the sc joints -->
  <!-- <joint name="${prefix}${name}_sc_joint" type="fixed"> -->
  <!-- <origin rpy="${rpy}" /> -->
  <!-- <parent link="${prefix}${name}" /> -->
  <!-- <child link="${prefix}${name}_sc" /> -->
  <!-- </joint> -->
  <joint name="arm_4_5" type="revolute">
    <origin rpy="-1.5707963267948966 0 0" xyz="-0.0825 0.384 0"/>
    <parent link="arm_4_link4"/>
    <child link="arm_4_link5"/>
    <axis xyz="0 0 1"/>
    <limit effort="12.0" lower="-2.8973" upper="2.8973" velocity="2.61"/>
    <safety_controller k_position="100.0" k_velocity="40.0" soft_lower_limit="-2.8973" soft_upper_limit="2.8973"/>
    <dynamics D="1" K="7000" damping="0.003" friction="0.0" mu_coulomb="0" mu_viscous="16"/>
  </joint>
  <!-- sub-link defining detailed meshes for collision with environment -->
  <link name="arm_4_link6">
    <visual>
      <geometry>
        <mesh filename="package://franka_description/meshes/visual/link6.dae"/>
      </geometry>
    </visual>
    <collision>
      <geometry>
        <mesh filename="package://franka_description/meshes/collision/link6.stl"/>
      </geometry>
    </collision>
  </link>
  <!-- sub-link defining coarse geometries of real robot's internal self-collision -->
  <!-- <link name="${prefix}${name}_sc">
      <xacro:unless value="${gazebo}">
        <xacro:insert_block name="self_collision_geometries" />
      </xacro:unless>
    </link> -->
  <!-- fixed joint between both sub-links -->
  <!-- <joint name="${prefix}${name}_sc_joint" type="fixed">
      <origin rpy="${rpy}" />
      <parent link="${prefix}${name}" />
      <child link="${prefix}${name}_sc" />
    </joint>
     -->
  <!-- Trying to remove the sc joints -->
  <!-- <joint name="${prefix}${name}_sc_joint" type="fixed"> -->
  <!-- <origin rpy="${rpy}" /> -->
  <!-- <parent link="${prefix}${name}" /> -->
  <!-- <child link="${prefix}${name}_sc" /> -->
  <!-- </joint> -->
  <joint name="arm_4_6" type="revolute">
    <origin rpy="1.5707963267948966 0 0" xyz="0 0 0"/>
    <parent link="arm_4_link5"/>
    <child link="arm_4_link6"/>
    <axis xyz="0 0 1"/>
    <limit effort="12.0" lower="-0.0175" upper="3.7525" velocity="2.61"/>
    <safety_controller k_position="100.0" k_velocity="40.0" soft_lower_limit="-0.0175" soft_upper_limit="3.7525"/>
    <dynamics D="1" K="7000" damping="0.003" friction="0.0" mu_coulomb="0" mu_viscous="16"/>
  </joint>
  <!-- sub-link defining detailed meshes for collision with environment -->
  <link name="arm_4_link7">
    <visual>
      <geometry>
        <mesh filename="package://franka_description/meshes/visual/link7.dae"/>
      </geometry>
    </visual>
    <collision>
      <geometry>
        <mesh filename="package://franka_description/meshes/collision/link7.stl"/>
      </geometry>
    </collision>
  </link>
  <!-- sub-link defining coarse geometries of real robot's internal self-collision -->
  <!-- <link name="${prefix}${name}_sc">
      <xacro:unless value="${gazebo}">
        <xacro:insert_block name="self_collision_geometries" />
      </xacro:unless>
    </link> -->
  <!-- fixed joint between both sub-links -->
  <!-- <joint name="${prefix}${name}_sc_joint" type="fixed">
      <origin rpy="${rpy}" />
      <parent link="${prefix}${name}" />
      <child link="${prefix}${name}_sc" />
    </joint>
     -->
  <!-- Trying to remove the sc joints -->
  <!-- <joint name="${prefix}${name}_sc_joint" type="fixed"> -->
  <!-- <origin rpy="${rpy}" /> -->
  <!-- <parent link="${prefix}${name}" /> -->
  <!-- <child link="${prefix}${name}_sc" /> -->
  <!-- </joint> -->
  <joint name="arm_4_7" type="revolute">
    <origin rpy="1.5707963267948966 0 0" xyz="0.088 0 0"/>
    <parent link="arm_4_link6"/>
    <child link="arm_4_link7"/>
    <axis xyz="0 0 1"/>
    <limit effort="12.0" lower="-2.8973" upper="2.8973" velocity="2.61"/>
    <safety_controller k_position="100.0" k_velocity="40.0" soft_lower_limit="-2.8973" soft_upper_limit="2.8973"/>
    <dynamics D="1" K="7000" damping="0.003" friction="0.0" mu_coulomb="0" mu_viscous="16"/>
  </joint>
  <link name="arm_4_link8"/>
  <joint name="arm_4_8" type="fixed">
    <origin rpy="0 0 0" xyz="0 0 0.107"/>
    <parent link="arm_4_link7"/>
    <child link="arm_4_link8"/>
  </joint>
  <joint name="arm_5_joint_shelf_5" type="fixed">
    <parent link="shelf_5"/>
    <child link="arm_5_link0"/>
    <origin rpy="0 0 0" xyz="0 0 0.2"/>
  </joint>
  <!-- sub-link defining detailed meshes for collision with environment -->
  <link name="arm_5_link0">
    <visual>
      <geometry>
        <mesh filename="package://franka_description/meshes/visual/link0.dae"/>
      </geometry>
    </visual>
    <collision>
      <geometry>
        <mesh filename="package://franka_description/meshes/collision/link0.stl"/>
      </geometry>
    </collision>
  </link>
  <!-- sub-link defining coarse geometries of real robot's internal self-collision -->
  <!-- <link name="${prefix}${name}_sc">
      <xacro:unless value="${gazebo}">
        <xacro:insert_block name="self_collision_geometries" />
      </xacro:unless>
    </link> -->
  <!-- fixed joint between both sub-links -->
  <!-- <joint name="${prefix}${name}_sc_joint" type="fixed">
      <origin rpy="${rpy}" />
      <parent link="${prefix}${name}" />
      <child link="${prefix}${name}_sc" />
    </joint>
     -->
  <!-- Trying to remove the sc joints -->
  <!-- <joint name="${prefix}${name}_sc_joint" type="fixed"> -->
  <!-- <origin rpy="${rpy}" /> -->
  <!-- <parent link="${prefix}${name}" /> -->
  <!-- <child link="${prefix}${name}_sc" /> -->
  <!-- </joint> -->
  <!-- sub-link defining detailed meshes for collision with environment -->
  <link name="arm_5_link1">
    <visual>
      <geometry>
        <mesh filename="package://franka_description/meshes/visual/link1.dae"/>
      </geometry>
    </visual>
    <collision>
      <geometry>
        <mesh filename="package://franka_description/meshes/collision/link1.stl"/>
      </geometry>
    </collision>
  </link>
  <!-- sub-link defining coarse geometries of real robot's internal self-collision -->
  <!-- <link name="${prefix}${name}_sc">
      <xacro:unless value="${gazebo}">
        <xacro:insert_block name="self_collision_geometries" />
      </xacro:unless>
    </link> -->
  <!-- fixed joint between both sub-links -->
  <!-- <joint name="${prefix}${name}_sc_joint" type="fixed">
      <origin rpy="${rpy}" />
      <parent link="${prefix}${name}" />
      <child link="${prefix}${name}_sc" />
    </joint>
     -->
  <!-- Trying to remove the sc joints -->
  <!-- <joint name="${prefix}${name}_sc_joint" type="fixed"> -->
  <!-- <origin rpy="${rpy}" /> -->
  <!-- <parent link="${prefix}${name}" /> -->
  <!-- <child link="${prefix}${name}_sc" /> -->
  <!-- </joint> -->
  <joint name="arm_5_1" type="revolute">
    <origin rpy="0 0 0" xyz="0 0 0.333"/>
    <parent link="arm_5_link0"/>
    <child link="arm_5_link1"/>
    <axis xyz="0 0 1"/>
    <limit effort="87.0" lower="-2.8973" upper="2.8973" velocity="2.175"/>
    <safety_controller k_position="100.0" k_velocity="40.0" soft_lower_limit="-2.8973" soft_upper_limit="2.8973"/>
    <dynamics D="1" K="7000" damping="0.003" friction="0.0" mu_coulomb="0" mu_viscous="16"/>
  </joint>
  <!-- sub-link defining detailed meshes for collision with environment -->
  <link name="arm_5_link2">
    <visual>
      <geometry>
        <mesh filename="package://franka_description/meshes/visual/link2.dae"/>
      </geometry>
    </visual>
    <collision>
      <geometry>
        <mesh filename="package://franka_description/meshes/collision/link2.stl"/>
      </geometry>
    </collision>
  </link>
  <!-- sub-link defining coarse geometries of real robot's internal self-collision -->
  <!-- <link name="${prefix}${name}_sc">
      <xacro:unless value="${gazebo}">
        <xacro:insert_block name="self_collision_geometries" />
      </xacro:unless>
    </link> -->
  <!-- fixed joint between both sub-links -->
  <!-- <joint name="${prefix}${name}_sc_joint" type="fixed">
      <origin rpy="${rpy}" />
      <parent link="${prefix}${name}" />
      <child link="${prefix}${name}_sc" />
    </joint>
     -->
  <!-- Trying to remove the sc joints -->
  <!-- <joint name="${prefix}${name}_sc_joint" type="fixed"> -->
  <!-- <origin rpy="${rpy}" /> -->
  <!-- <parent link="${prefix}${name}" /> -->
  <!-- <child link="${prefix}${name}_sc" /> -->
  <!-- </joint> -->
  <joint name="arm_5_2" type="revolute">
    <origin rpy="-1.5707963267948966 0 0" xyz="0 0 0"/>
    <parent link="arm_5_link1"/>
    <child link="arm_5_link2"/>
    <axis xyz="0 0 1"/>
    <limit effort="87.0" lower="-1.7628" upper="1.7628" velocity="2.175"/>
    <safety_controller k_position="100.0" k_velocity="40.0" soft_lower_limit="-1.7628" soft_upper_limit="1.7628"/>
    <dynamics D="1" K="7000" damping="0.003" friction="0.0" mu_coulomb="0" mu_viscous="16"/>
  </joint>
  <!-- sub-link defining detailed meshes for collision with environment -->
  <link name="arm_5_link3">
    <visual>
      <geometry>
        <mesh filename="package://franka_description/meshes/visual/link3.dae"/>
      </geometry>
    </visual>
    <collision>
      <geometry>
        <mesh filename="package://franka_description/meshes/collision/link3.stl"/>
      </geometry>
    </collision>
  </link>
  <!-- sub-link defining coarse geometries of real robot's internal self-collision -->
  <!-- <link name="${prefix}${name}_sc">
      <xacro:unless value="${gazebo}">
        <xacro:insert_block name="self_collision_geometries" />
      </xacro:unless>
    </link> -->
  <!-- fixed joint between both sub-links -->
  <!-- <joint name="${prefix}${name}_sc_joint" type="fixed">
      <origin rpy="${rpy}" />
      <parent link="${prefix}${name}" />
      <child link="${prefix}${name}_sc" />
    </joint>
     -->
  <!-- Trying to remove the sc joints -->
  <!-- <joint name="${prefix}${name}_sc_joint" type="fixed"> -->
  <!-- <origin rpy="${rpy}" /> -->
  <!-- <parent link="${prefix}${name}" /> -->
  <!-- <child link="${prefix}${name}_sc" /> -->
  <!-- </joint> -->
  <joint name="arm_5_3" type="revolute">
    <origin rpy="1.5707963267948966 0 0" xyz="0 -0.316 0"/>
    <parent link="arm_5_link2"/>
    <child link="arm_5_link3"/>
    <axis xyz="0 0 1"/>
    <limit effort="87.0" lower="-2.8973" upper="2.8973" velocity="2.175"/>
    <safety_controller k_position="100.0" k_velocity="40.0" soft_lower_limit="-2.8973" soft_upper_limit="2.8973"/>
    <dynamics D="1" K="7000" damping="0.003" friction="0.0" mu_coulomb="0" mu_viscous="16"/>
  </joint>
  <!-- sub-link defining detailed meshes for collision with environment -->
  <link name="arm_5_link4">
    <visual>
      <geometry>
        <mesh filename="package://franka_description/meshes/visual/link4.dae"/>
      </geometry>
    </visual>
    <collision>
      <geometry>
        <mesh filename="package://franka_description/meshes/collision/link4.stl"/>
      </geometry>
    </collision>
  </link>
  <!-- sub-link defining coarse geometries of real robot's internal self-collision -->
  <!-- <link name="${prefix}${name}_sc">
      <xacro:unless value="${gazebo}">
        <xacro:insert_block name="self_collision_geometries" />
      </xacro:unless>
    </link> -->
  <!-- fixed joint between both sub-links -->
  <!-- <joint name="${prefix}${name}_sc_joint" type="fixed">
      <origin rpy="${rpy}" />
      <parent link="${prefix}${name}" />
      <child link="${prefix}${name}_sc" />
    </joint>
     -->
  <!-- Trying to remove the sc joints -->
  <!-- <joint name="${prefix}${name}_sc_joint" type="fixed"> -->
  <!-- <origin rpy="${rpy}" /> -->
  <!-- <parent link="${prefix}${name}" /> -->
  <!-- <child link="${prefix}${name}_sc" /> -->
  <!-- </joint> -->
  <joint name="arm_5_4" type="revolute">
    <origin rpy="1.5707963267948966 0 0" xyz="0.0825 0 0"/>
    <parent link="arm_5_link3"/>
    <child link="arm_5_link4"/>
    <axis xyz="0 0 1"/>
    <limit effort="87.0" lower="-3.0718" upper="-0.0698" velocity="2.175"/>
    <safety_controller k_position="100.0" k_velocity="40.0" soft_lower_limit="-3.0718" soft_upper_limit="-0.0698"/>
    <dynamics D="1" K="7000" damping="0.003" friction="0.0" mu_coulomb="0" mu_viscous="16"/>
  </joint>
  <!-- sub-link defining detailed meshes for collision with environment -->
  <link name="arm_5_link5">
    <visual>
      <geometry>
        <mesh filename="package://franka_description/meshes/visual/link5.dae"/>
      </geometry>
    </visual>
    <collision>
      <geometry>
        <mesh filename="package://franka_description/meshes/collision/link5.stl"/>
      </geometry>
    </collision>
  </link>
  <!-- sub-link defining coarse geometries of real robot's internal self-collision -->
  <!-- <link name="${prefix}${name}_sc">
      <xacro:unless value="${gazebo}">
        <xacro:insert_block name="self_collision_geometries" />
      </xacro:unless>
    </link> -->
  <!-- fixed joint between both sub-links -->
  <!-- <joint name="${prefix}${name}_sc_joint" type="fixed">
      <origin rpy="${rpy}" />
      <parent link="${prefix}${name}" />
      <child link="${prefix}${name}_sc" />
    </joint>
     -->
  <!-- Trying to remove the sc joints -->
  <!-- <joint name="${prefix}${name}_sc_joint" type="fixed"> -->
  <!-- <origin rpy="${rpy}" /> -->
  <!-- <parent link="${prefix}${name}" /> -->
  <!-- <child link="${prefix}${name}_sc" /> -->
  <!-- </joint> -->
  <joint name="arm_5_5" type="revolute">
    <origin rpy="-1.5707963267948966 0 0" xyz="-0.0825 0.384 0"/>
    <parent link="arm_5_link4"/>
    <child link="arm_5_link5"/>
    <axis xyz="0 0 1"/>
    <limit effort="12.0" lower="-2.8973" upper="2.8973" velocity="2.61"/>
    <safety_controller k_position="100.0" k_velocity="40.0" soft_lower_limit="-2.8973" soft_upper_limit="2.8973"/>
    <dynamics D="1" K="7000" damping="0.003" friction="0.0" mu_coulomb="0" mu_viscous="16"/>
  </joint>
  <!-- sub-link defining detailed meshes for collision with environment -->
  <link name="arm_5_link6">
    <visual>
      <geometry>
        <mesh filename="package://franka_description/meshes/visual/link6.dae"/>
      </geometry>
    </visual>
    <collision>
      <geometry>
        <mesh filename="package://franka_description/meshes/collision/link6.stl"/>
      </geometry>
    </collision>
  </link>
  <!-- sub-link defining coarse geometries of real robot's internal self-collision -->
  <!-- <link name="${prefix}${name}_sc">
      <xacro:unless value="${gazebo}">
        <xacro:insert_block name="self_collision_geometries" />
      </xacro:unless>
    </link> -->
  <!-- fixed joint between both sub-links -->
  <!-- <joint name="${prefix}${name}_sc_joint" type="fixed">
      <origin rpy="${rpy}" />
      <parent link="${prefix}${name}" />
      <child link="${prefix}${name}_sc" />
    </joint>
     -->
  <!-- Trying to remove the sc joints -->
  <!-- <joint name="${prefix}${name}_sc_joint" type="fixed"> -->
  <!-- <origin rpy="${rpy}" /> -->
  <!-- <parent link="${prefix}${name}" /> -->
  <!-- <child link="${prefix}${name}_sc" /> -->
  <!-- </joint> -->
  <joint name="arm_5_6" type="revolute">
    <origin rpy="1.5707963267948966 0 0" xyz="0 0 0"/>
    <parent link="arm_5_link5"/>
    <child link="arm_5_link6"/>
    <axis xyz="0 0 1"/>
    <limit effort="12.0" lower="-0.0175" upper="3.7525" velocity="2.61"/>
    <safety_controller k_position="100.0" k_velocity="40.0" soft_lower_limit="-0.0175" soft_upper_limit="3.7525"/>
    <dynamics D="1" K="7000" damping="0.003" friction="0.0" mu_coulomb="0" mu_viscous="16"/>
  </joint>
  <!-- sub-link defining detailed meshes for collision with environment -->
  <link name="arm_5_link7">
    <visual>
      <geometry>
        <mesh filename="package://franka_description/meshes/visual/link7.dae"/>
      </geometry>
    </visual>
    <collision>
      <geometry>
        <mesh filename="package://franka_description/meshes/collision/link7.stl"/>
      </geometry>
    </collision>
  </link>
  <!-- sub-link defining coarse geometries of real robot's internal self-collision -->
  <!-- <link name="${prefix}${name}_sc">
      <xacro:unless value="${gazebo}">
        <xacro:insert_block name="self_collision_geometries" />
      </xacro:unless>
    </link> -->
  <!-- fixed joint between both sub-links -->
  <!-- <joint name="${prefix}${name}_sc_joint" type="fixed">
      <origin rpy="${rpy}" />
      <parent link="${prefix}${name}" />
      <child link="${prefix}${name}_sc" />
    </joint>
     -->
  <!-- Trying to remove the sc joints -->
  <!-- <joint name="${prefix}${name}_sc_joint" type="fixed"> -->
  <!-- <origin rpy="${rpy}" /> -->
  <!-- <parent link="${prefix}${name}" /> -->
  <!-- <child link="${prefix}${name}_sc" /> -->
  <!-- </joint> -->
  <joint name="arm_5_7" type="revolute">
    <origin rpy="1.5707963267948966 0 0" xyz="0.088 0 0"/>
    <parent link="arm_5_link6"/>
    <child link="arm_5_link7"/>
    <axis xyz="0 0 1"/>
    <limit effort="12.0" lower="-2.8973" upper="2.8973" velocity="2.61"/>
    <safety_controller k_position="100.0" k_velocity="40.0" soft_lower_limit="-2.8973" soft_upper_limit="2.8973"/>
    <dynamics D="1" K="7000" damping="0.003" friction="0.0" mu_coulomb="0" mu_viscous="16"/>
  </joint>
  <link name="arm_5_link8"/>
  <joint name="arm_5_8" type="fixed">
    <origin rpy="0 0 0" xyz="0 0 0.107"/>
    <parent link="arm_5_link7"/>
    <child link="arm_5_link8"/>
  </joint>
  <joint name="arm_6_joint_shelf_6" type="fixed">
    <parent link="shelf_6"/>
    <child link="arm_6_link0"/>
    <origin rpy="0 0 0" xyz="0 0 0.2"/>
  </joint>
  <!-- sub-link defining detailed meshes for collision with environment -->
  <link name="arm_6_link0">
    <visual>
      <geometry>
        <mesh filename="package://franka_description/meshes/visual/link0.dae"/>
      </geometry>
    </visual>
    <collision>
      <geometry>
        <mesh filename="package://franka_description/meshes/collision/link0.stl"/>
      </geometry>
    </collision>
  </link>
  <!-- sub-link defining coarse geometries of real robot's internal self-collision -->
  <!-- <link name="${prefix}${name}_sc">
      <xacro:unless value="${gazebo}">
        <xacro:insert_block name="self_collision_geometries" />
      </xacro:unless>
    </link> -->
  <!-- fixed joint between both sub-links -->
  <!-- <joint name="${prefix}${name}_sc_joint" type="fixed">
      <origin rpy="${rpy}" />
      <parent link="${prefix}${name}" />
      <child link="${prefix}${name}_sc" />
    </joint>
     -->
  <!-- Trying to remove the sc joints -->
  <!-- <joint name="${prefix}${name}_sc_joint" type="fixed"> -->
  <!-- <origin rpy="${rpy}" /> -->
  <!-- <parent link="${prefix}${name}" /> -->
  <!-- <child link="${prefix}${name}_sc" /> -->
  <!-- </joint> -->
  <!-- sub-link defining detailed meshes for collision with environment -->
  <link name="arm_6_link1">
    <visual>
      <geometry>
        <mesh filename="package://franka_description/meshes/visual/link1.dae"/>
      </geometry>
    </visual>
    <collision>
      <geometry>
        <mesh filename="package://franka_description/meshes/collision/link1.stl"/>
      </geometry>
    </collision>
  </link>
  <!-- sub-link defining coarse geometries of real robot's internal self-collision -->
  <!-- <link name="${prefix}${name}_sc">
      <xacro:unless value="${gazebo}">
        <xacro:insert_block name="self_collision_geometries" />
      </xacro:unless>
    </link> -->
  <!-- fixed joint between both sub-links -->
  <!-- <joint name="${prefix}${name}_sc_joint" type="fixed">
      <origin rpy="${rpy}" />
      <parent link="${prefix}${name}" />
      <child link="${prefix}${name}_sc" />
    </joint>
     -->
  <!-- Trying to remove the sc joints -->
  <!-- <joint name="${prefix}${name}_sc_joint" type="fixed"> -->
  <!-- <origin rpy="${rpy}" /> -->
  <!-- <parent link="${prefix}${name}" /> -->
  <!-- <child link="${prefix}${name}_sc" /> -->
  <!-- </joint> -->
  <joint name="arm_6_1" type="revolute">
    <origin rpy="0 0 0" xyz="0 0 0.333"/>
    <parent link="arm_6_link0"/>
    <child link="arm_6_link1"/>
    <axis xyz="0 0 1"/>
    <limit effort="87.0" lower="-2.8973" upper="2.8973" velocity="2.175"/>
    <safety_controller k_position="100.0" k_velocity="40.0" soft_lower_limit="-2.8973" soft_upper_limit="2.8973"/>
    <dynamics D="1" K="7000" damping="0.003" friction="0.0" mu_coulomb="0" mu_viscous="16"/>
  </joint>
  <!-- sub-link defining detailed meshes for collision with environment -->
  <link name="arm_6_link2">
    <visual>
      <geometry>
        <mesh filename="package://franka_description/meshes/visual/link2.dae"/>
      </geometry>
    </visual>
    <collision>
      <geometry>
        <mesh filename="package://franka_description/meshes/collision/link2.stl"/>
      </geometry>
    </collision>
  </link>
  <!-- sub-link defining coarse geometries of real robot's internal self-collision -->
  <!-- <link name="${prefix}${name}_sc">
      <xacro:unless value="${gazebo}">
        <xacro:insert_block name="self_collision_geometries" />
      </xacro:unless>
    </link> -->
  <!-- fixed joint between both sub-links -->
  <!-- <joint name="${prefix}${name}_sc_joint" type="fixed">
      <origin rpy="${rpy}" />
      <parent link="${prefix}${name}" />
      <child link="${prefix}${name}_sc" />
    </joint>
     -->
  <!-- Trying to remove the sc joints -->
  <!-- <joint name="${prefix}${name}_sc_joint" type="fixed"> -->
  <!-- <origin rpy="${rpy}" /> -->
  <!-- <parent link="${prefix}${name}" /> -->
  <!-- <child link="${prefix}${name}_sc" /> -->
  <!-- </joint> -->
  <joint name="arm_6_2" type="revolute">
    <origin rpy="-1.5707963267948966 0 0" xyz="0 0 0"/>
    <parent link="arm_6_link1"/>
    <child link="arm_6_link2"/>
    <axis xyz="0 0 1"/>
    <limit effort="87.0" lower="-1.7628" upper="1.7628" velocity="2.175"/>
    <safety_controller k_position="100.0" k_velocity="40.0" soft_lower_limit="-1.7628" soft_upper_limit="1.7628"/>
    <dynamics D="1" K="7000" damping="0.003" friction="0.0" mu_coulomb="0" mu_viscous="16"/>
  </joint>
  <!-- sub-link defining detailed meshes for collision with environment -->
  <link name="arm_6_link3">
    <visual>
      <geometry>
        <mesh filename="package://franka_description/meshes/visual/link3.dae"/>
      </geometry>
    </visual>
    <collision>
      <geometry>
        <mesh filename="package://franka_description/meshes/collision/link3.stl"/>
      </geometry>
    </collision>
  </link>
  <!-- sub-link defining coarse geometries of real robot's internal self-collision -->
  <!-- <link name="${prefix}${name}_sc">
      <xacro:unless value="${gazebo}">
        <xacro:insert_block name="self_collision_geometries" />
      </xacro:unless>
    </link> -->
  <!-- fixed joint between both sub-links -->
  <!-- <joint name="${prefix}${name}_sc_joint" type="fixed">
      <origin rpy="${rpy}" />
      <parent link="${prefix}${name}" />
      <child link="${prefix}${name}_sc" />
    </joint>
     -->
  <!-- Trying to remove the sc joints -->
  <!-- <joint name="${prefix}${name}_sc_joint" type="fixed"> -->
  <!-- <origin rpy="${rpy}" /> -->
  <!-- <parent link="${prefix}${name}" /> -->
  <!-- <child link="${prefix}${name}_sc" /> -->
  <!-- </joint> -->
  <joint name="arm_6_3" type="revolute">
    <origin rpy="1.5707963267948966 0 0" xyz="0 -0.316 0"/>
    <parent link="arm_6_link2"/>
    <child link="arm_6_link3"/>
    <axis xyz="0 0 1"/>
    <limit effort="87.0" lower="-2.8973" upper="2.8973" velocity="2.175"/>
    <safety_controller k_position="100.0" k_velocity="40.0" soft_lower_limit="-2.8973" soft_upper_limit="2.8973"/>
    <dynamics D="1" K="7000" damping="0.003" friction="0.0" mu_coulomb="0" mu_viscous="16"/>
  </joint>
  <!-- sub-link defining detailed meshes for collision with environment -->
  <link name="arm_6_link4">
    <visual>
      <geometry>
        <mesh filename="package://franka_description/meshes/visual/link4.dae"/>
      </geometry>
    </visual>
    <collision>
      <geometry>
        <mesh filename="package://franka_description/meshes/collision/link4.stl"/>
      </geometry>
    </collision>
  </link>
  <!-- sub-link defining coarse geometries of real robot's internal self-collision -->
  <!-- <link name="${prefix}${name}_sc">
      <xacro:unless value="${gazebo}">
        <xacro:insert_block name="self_collision_geometries" />
      </xacro:unless>
    </link> -->
  <!-- fixed joint between both sub-links -->
  <!-- <joint name="${prefix}${name}_sc_joint" type="fixed">
      <origin rpy="${rpy}" />
      <parent link="${prefix}${name}" />
      <child link="${prefix}${name}_sc" />
    </joint>
     -->
  <!-- Trying to remove the sc joints -->
  <!-- <joint name="${prefix}${name}_sc_joint" type="fixed"> -->
  <!-- <origin rpy="${rpy}" /> -->
  <!-- <parent link="${prefix}${name}" /> -->
  <!-- <child link="${prefix}${name}_sc" /> -->
  <!-- </joint> -->
  <joint name="arm_6_4" type="revolute">
    <origin rpy="1.5707963267948966 0 0" xyz="0.0825 0 0"/>
    <parent link="arm_6_link3"/>
    <child link="arm_6_link4"/>
    <axis xyz="0 0 1"/>
    <limit effort="87.0" lower="-3.0718" upper="-0.0698" velocity="2.175"/>
    <safety_controller k_position="100.0" k_velocity="40.0" soft_lower_limit="-3.0718" soft_upper_limit="-0.0698"/>
    <dynamics D="1" K="7000" damping="0.003" friction="0.0" mu_coulomb="0" mu_viscous="16"/>
  </joint>
  <!-- sub-link defining detailed meshes for collision with environment -->
  <link name="arm_6_link5">
    <visual>
      <geometry>
        <mesh filename="package://franka_description/meshes/visual/link5.dae"/>
      </geometry>
    </visual>
    <collision>
      <geometry>
        <mesh filename="package://franka_description/meshes/collision/link5.stl"/>
      </geometry>
    </collision>
  </link>
  <!-- sub-link defining coarse geometries of real robot's internal self-collision -->
  <!-- <link name="${prefix}${name}_sc">
      <xacro:unless value="${gazebo}">
        <xacro:insert_block name="self_collision_geometries" />
      </xacro:unless>
    </link> -->
  <!-- fixed joint between both sub-links -->
  <!-- <joint name="${prefix}${name}_sc_joint" type="fixed">
      <origin rpy="${rpy}" />
      <parent link="${prefix}${name}" />
      <child link="${prefix}${name}_sc" />
    </joint>
     -->
  <!-- Trying to remove the sc joints -->
  <!-- <joint name="${prefix}${name}_sc_joint" type="fixed"> -->
  <!-- <origin rpy="${rpy}" /> -->
  <!-- <parent link="${prefix}${name}" /> -->
  <!-- <child link="${prefix}${name}_sc" /> -->
  <!-- </joint> -->
  <joint name="arm_6_5" type="revolute">
    <origin rpy="-1.5707963267948966 0 0" xyz="-0.0825 0.384 0"/>
    <parent link="arm_6_link4"/>
    <child link="arm_6_link5"/>
    <axis xyz="0 0 1"/>
    <limit effort="12.0" lower="-2.8973" upper="2.8973" velocity="2.61"/>
    <safety_controller k_position="100.0" k_velocity="40.0" soft_lower_limit="-2.8973" soft_upper_limit="2.8973"/>
    <dynamics D="1" K="7000" damping="0.003" friction="0.0" mu_coulomb="0" mu_viscous="16"/>
  </joint>
  <!-- sub-link defining detailed meshes for collision with environment -->
  <link name="arm_6_link6">
    <visual>
      <geometry>
        <mesh filename="package://franka_description/meshes/visual/link6.dae"/>
      </geometry>
    </visual>
    <collision>
      <geometry>
        <mesh filename="package://franka_description/meshes/collision/link6.stl"/>
      </geometry>
    </collision>
  </link>
  <!-- sub-link defining coarse geometries of real robot's internal self-collision -->
  <!-- <link name="${prefix}${name}_sc">
      <xacro:unless value="${gazebo}">
        <xacro:insert_block name="self_collision_geometries" />
      </xacro:unless>
    </link> -->
  <!-- fixed joint between both sub-links -->
  <!-- <joint name="${prefix}${name}_sc_joint" type="fixed">
      <origin rpy="${rpy}" />
      <parent link="${prefix}${name}" />
      <child link="${prefix}${name}_sc" />
    </joint>
     -->
  <!-- Trying to remove the sc joints -->
  <!-- <joint name="${prefix}${name}_sc_joint" type="fixed"> -->
  <!-- <origin rpy="${rpy}" /> -->
  <!-- <parent link="${prefix}${name}" /> -->
  <!-- <child link="${prefix}${name}_sc" /> -->
  <!-- </joint> -->
  <joint name="arm_6_6" type="revolute">
    <origin rpy="1.5707963267948966 0 0" xyz="0 0 0"/>
    <parent link="arm_6_link5"/>
    <child link="arm_6_link6"/>
    <axis xyz="0 0 1"/>
    <limit effort="12.0" lower="-0.0175" upper="3.7525" velocity="2.61"/>
    <safety_controller k_position="100.0" k_velocity="40.0" soft_lower_limit="-0.0175" soft_upper_limit="3.7525"/>
    <dynamics D="1" K="7000" damping="0.003" friction="0.0" mu_coulomb="0" mu_viscous="16"/>
  </joint>
  <!-- sub-link defining detailed meshes for collision with environment -->
  <link name="arm_6_link7">
    <visual>
      <geometry>
        <mesh filename="package://franka_description/meshes/visual/link7.dae"/>
      </geometry>
    </visual>
    <collision>
      <geometry>
        <mesh filename="package://franka_description/meshes/collision/link7.stl"/>
      </geometry>
    </collision>
  </link>
  <!-- sub-link defining coarse geometries of real robot's internal self-collision -->
  <!-- <link name="${prefix}${name}_sc">
      <xacro:unless value="${gazebo}">
        <xacro:insert_block name="self_collision_geometries" />
      </xacro:unless>
    </link> -->
  <!-- fixed joint between both sub-links -->
  <!-- <joint name="${prefix}${name}_sc_joint" type="fixed">
      <origin rpy="${rpy}" />
      <parent link="${prefix}${name}" />
      <child link="${prefix}${name}_sc" />
    </joint>
     -->
  <!-- Trying to remove the sc joints -->
  <!-- <joint name="${prefix}${name}_sc_joint" type="fixed"> -->
  <!-- <origin rpy="${rpy}" /> -->
  <!-- <parent link="${prefix}${name}" /> -->
  <!-- <child link="${prefix}${name}_sc" /> -->
  <!-- </joint> -->
  <joint name="arm_6_7" type="revolute">
    <origin rpy="1.5707963267948966 0 0" xyz="0.088 0 0"/>
    <parent link="arm_6_link6"/>
    <child link="arm_6_link7"/>
    <axis xyz="0 0 1"/>
    <limit effort="12.0" lower="-2.8973" upper="2.8973" velocity="2.61"/>
    <safety_controller k_position="100.0" k_velocity="40.0" soft_lower_limit="-2.8973" soft_upper_limit="2.8973"/>
    <dynamics D="1" K="7000" damping="0.003" friction="0.0" mu_coulomb="0" mu_viscous="16"/>
  </joint>
  <link name="arm_6_link8"/>
  <joint name="arm_6_8" type="fixed">
    <origin rpy="0 0 0" xyz="0 0 0.107"/>
    <parent link="arm_6_link7"/>
    <child link="arm_6_link8"/>
  </joint>
</robot>
