<?xml version="1.0" ?>
<!-- =================================================================================== -->
<!-- |    This document was autogenerated by xacro from world_multi_mobile.xacro       | -->
<!-- |    EDITING THIS FILE BY HAND IS NOT RECOMMENDED                                 | -->
<!-- =================================================================================== -->
<robot name="world_no_shelves_mobile_4">
  <!-- <xacro:walls_world/> -->
  <material name="blue">
    <color rgba="0 0 0.8 1"/>
  </material>
  <material name="white">
    <color rgba="1 1 1 1"/>
  </material>
  <material name="green">
    <color rgba="0 0.8 0 1"/>
  </material>
  <material name="black">
    <color rgba="0 0 0 1"/>
  </material>
  <!-- Did not set a default for the name of the robot to require a name -->
  <!-- Follow the convention "mobile_1" -->
  <!-- Expected dims 0.25 unless the map changes -->
  <!-- <xacro:mobile_robot name="mobile_bot_1" dims="0.25" color="white"/> -->
  <link name="world_center"/>
  <link name="world"/>
  <joint name="world_center_to_world" type="fixed">
    <parent link="world_center"/>
    <child link="world"/>
    <origin rpy="0 0 0" xyz="-5.0 -5.0 0"/>
  </joint>
  <!-- Setup the first wall -->
  <link name="wall_right" type="fixed">
    <visual>
      <geometry>
        <box size="10.0 0.1 1"/>
      </geometry>
      <origin rpy="0 0 0" xyz="5.0 -0.060000000000000005 0"/>
    </visual>
    <collision>
      <geometry>
        <box size="10.0 0.1 1"/>
      </geometry>
      <origin rpy="0 0 0" xyz="5.0 -0.060000000000000005 0"/>
    </collision>
  </link>
  <joint name="world_to_right" type="fixed">
    <parent link="world"/>
    <child link="wall_right"/>
    <origin rpy="0 0 0" xyz="0 0 0.5"/>
  </joint>
  <!-- Setup the second wall -->
  <link name="wall_front">
    <visual>
      <geometry>
        <box size="10.0 0.1 1"/>
      </geometry>
      <origin rpy="0 0 0" xyz="5.0 -0.060000000000000005 0"/>
    </visual>
    <collision>
      <geometry>
        <box size="10.0 0.1 1"/>
      </geometry>
      <origin rpy="0 0 0" xyz="5.0 -0.060000000000000005 0"/>
    </collision>
  </link>
  <joint name="right_to_front" type="fixed">
    <parent link="wall_right"/>
    <child link="wall_front"/>
    <origin rpy="0 0 1.5708" xyz="10.0 0 0"/>
  </joint>
  <!-- Setup the third wall -->
  <link name="wall_left">
    <visual>
      <geometry>
        <box size="10.0 0.1 1"/>
      </geometry>
      <origin rpy="0 0 0" xyz="5.0 -0.060000000000000005 0"/>
    </visual>
    <collision>
      <geometry>
        <box size="10.0 0.1 1"/>
      </geometry>
      <origin rpy="0 0 0" xyz="5.0 -0.060000000000000005 0"/>
    </collision>
  </link>
  <joint name="front_to_left" type="fixed">
    <parent link="wall_front"/>
    <child link="wall_left"/>
    <origin rpy="0 0 1.5708" xyz="10.0 0 0"/>
  </joint>
  <!-- Setup the fourth wall -->
  <link name="wall_back">
    <visual>
      <geometry>
        <box size="10.0 0.1 1"/>
      </geometry>
      <origin rpy="0 0 0" xyz="5.0 -0.060000000000000005 0"/>
    </visual>
    <collision>
      <geometry>
        <box size="10.0 0.1 1"/>
      </geometry>
      <origin rpy="0 0 0" xyz="5.0 -0.060000000000000005 0"/>
    </collision>
  </link>
  <joint name="left_to_back" type="fixed">
    <parent link="wall_left"/>
    <child link="wall_back"/>
    <origin rpy="0 0 1.5708" xyz="10.0 0 0"/>
  </joint>
  <material name="pickup_shelf_color">
    <color rgba="0.5 0.5 0.5 0.99"/>
  </material>
  <link name="pickup_point_1">
    <visual>
      <geometry>
        <box size="0.5 0.5 1.3"/>
      </geometry>
      <material name="pickup_shelf_color"/>
      <origin rpy="0 0 0" xyz="0 0 0.65"/>
    </visual>
    <collision>
      <geometry>
        <box size="0.5 0.5 1.3"/>
      </geometry>
      <origin rpy="0 0 0" xyz="0 0 0.65"/>
    </collision>
  </link>
  <joint name="world_to_pickup_point_1" type="fixed">
    <parent link="world"/>
    <child link="pickup_point_1"/>
    <origin rpy="0 0 0" xyz="2.5 0.25 0"/>
  </joint>
  <link name="pickup_point_2">
    <visual>
      <geometry>
        <box size="0.5 0.5 1.3"/>
      </geometry>
      <material name="pickup_shelf_color"/>
      <origin rpy="0 0 0" xyz="0 0 0.65"/>
    </visual>
    <collision>
      <geometry>
        <box size="0.5 0.5 1.3"/>
      </geometry>
      <origin rpy="0 0 0" xyz="0 0 0.65"/>
    </collision>
  </link>
  <joint name="world_to_pickup_point_2" type="fixed">
    <parent link="world"/>
    <child link="pickup_point_2"/>
    <origin rpy="0 0 0" xyz="5.0 0.25 0"/>
  </joint>
  <link name="pickup_point_3">
    <visual>
      <geometry>
        <box size="0.5 0.5 1.3"/>
      </geometry>
      <material name="pickup_shelf_color"/>
      <origin rpy="0 0 0" xyz="0 0 0.65"/>
    </visual>
    <collision>
      <geometry>
        <box size="0.5 0.5 1.3"/>
      </geometry>
      <origin rpy="0 0 0" xyz="0 0 0.65"/>
    </collision>
  </link>
  <joint name="world_to_pickup_point_3" type="fixed">
    <parent link="world"/>
    <child link="pickup_point_3"/>
    <origin rpy="0 0 0" xyz="7.5 0.25 0"/>
  </joint>
  <link name="pickup_point_4">
    <visual>
      <geometry>
        <box size="0.5 0.5 1.3"/>
      </geometry>
      <material name="pickup_shelf_color"/>
      <origin rpy="0 0 0" xyz="0 0 0.65"/>
    </visual>
    <collision>
      <geometry>
        <box size="0.5 0.5 1.3"/>
      </geometry>
      <origin rpy="0 0 0" xyz="0 0 0.65"/>
    </collision>
  </link>
  <joint name="world_to_pickup_point_4" type="fixed">
    <parent link="world"/>
    <child link="pickup_point_4"/>
    <origin rpy="0 0 0" xyz="0.25 2.5 0"/>
  </joint>
  <link name="pickup_point_5">
    <visual>
      <geometry>
        <box size="0.5 0.5 1.3"/>
      </geometry>
      <material name="pickup_shelf_color"/>
      <origin rpy="0 0 0" xyz="0 0 0.65"/>
    </visual>
    <collision>
      <geometry>
        <box size="0.5 0.5 1.3"/>
      </geometry>
      <origin rpy="0 0 0" xyz="0 0 0.65"/>
    </collision>
  </link>
  <joint name="world_to_pickup_point_5" type="fixed">
    <parent link="world"/>
    <child link="pickup_point_5"/>
    <origin rpy="0 0 0" xyz="0.25 5.0 0"/>
  </joint>
  <link name="pickup_point_6">
    <visual>
      <geometry>
        <box size="0.5 0.5 1.3"/>
      </geometry>
      <material name="pickup_shelf_color"/>
      <origin rpy="0 0 0" xyz="0 0 0.65"/>
    </visual>
    <collision>
      <geometry>
        <box size="0.5 0.5 1.3"/>
      </geometry>
      <origin rpy="0 0 0" xyz="0 0 0.65"/>
    </collision>
  </link>
  <joint name="world_to_pickup_point_6" type="fixed">
    <parent link="world"/>
    <child link="pickup_point_6"/>
    <origin rpy="0 0 0" xyz="0.25 7.5 0"/>
  </joint>
  <link name="pickup_point_7">
    <visual>
      <geometry>
        <box size="0.5 0.5 1.3"/>
      </geometry>
      <material name="pickup_shelf_color"/>
      <origin rpy="0 0 0" xyz="0 0 0.65"/>
    </visual>
    <collision>
      <geometry>
        <box size="0.5 0.5 1.3"/>
      </geometry>
      <origin rpy="0 0 0" xyz="0 0 0.65"/>
    </collision>
  </link>
  <joint name="world_to_pickup_point_7" type="fixed">
    <parent link="world"/>
    <child link="pickup_point_7"/>
    <origin rpy="0 0 0" xyz="2.5 9.75 0"/>
  </joint>
  <link name="pickup_point_8">
    <visual>
      <geometry>
        <box size="0.5 0.5 1.3"/>
      </geometry>
      <material name="pickup_shelf_color"/>
      <origin rpy="0 0 0" xyz="0 0 0.65"/>
    </visual>
    <collision>
      <geometry>
        <box size="0.5 0.5 1.3"/>
      </geometry>
      <origin rpy="0 0 0" xyz="0 0 0.65"/>
    </collision>
  </link>
  <joint name="world_to_pickup_point_8" type="fixed">
    <parent link="world"/>
    <child link="pickup_point_8"/>
    <origin rpy="0 0 0" xyz="5.0 9.75 0"/>
  </joint>
  <link name="pickup_point_9">
    <visual>
      <geometry>
        <box size="0.5 0.5 1.3"/>
      </geometry>
      <material name="pickup_shelf_color"/>
      <origin rpy="0 0 0" xyz="0 0 0.65"/>
    </visual>
    <collision>
      <geometry>
        <box size="0.5 0.5 1.3"/>
      </geometry>
      <origin rpy="0 0 0" xyz="0 0 0.65"/>
    </collision>
  </link>
  <joint name="world_to_pickup_point_9" type="fixed">
    <parent link="world"/>
    <child link="pickup_point_9"/>
    <origin rpy="0 0 0" xyz="7.5 9.75 0"/>
  </joint>
  <!-- ############# -->
  <!-- Dropoff point -->
  <!-- ############# -->
  <link name="dropoff_point">
    <visual>
      <geometry>
        <box size="0.5 2 1.3"/>
      </geometry>
      <!-- <material name="pickup_shelf_color"/> -->
      <origin rpy="0 0 0" xyz="0 0 0.65"/>
    </visual>
    <collision>
      <geometry>
        <box size="0.5 2 1.3"/>
      </geometry>
      <origin rpy="0 0 0" xyz="0 0 0.65"/>
    </collision>
  </link>
  <joint name="world_to_dropoff_point" type="fixed">
    <parent link="world"/>
    <child link="dropoff_point"/>
    <origin rpy="0 0 0" xyz="9.75 5.0 0"/>
  </joint>
  <link default="mobile_bot_unnamed" name="mobile_1">
    <visual>
      <geometry>
        <cylinder length="0.5" radius="0.25"/>
      </geometry>
      <material name="white"/>
      <origin rpy="0 0 0" xyz="0 0 0.25"/>
    </visual>
    <collision>
      <geometry>
        <cylinder length="0.5" radius="0.25"/>
      </geometry>
      <origin rpy="0 0 0" xyz="0 0 0.25"/>
    </collision>
  </link>
  <link name="mobile_1_temp"/>
  <link default="mobile_bot_unnamed" name="mobile_2">
    <visual>
      <geometry>
        <cylinder length="0.5" radius="0.25"/>
      </geometry>
      <material name="green"/>
      <origin rpy="0 0 0" xyz="0 0 0.25"/>
    </visual>
    <collision>
      <geometry>
        <cylinder length="0.5" radius="0.25"/>
      </geometry>
      <origin rpy="0 0 0" xyz="0 0 0.25"/>
    </collision>
  </link>
  <link name="mobile_2_temp"/>
  <link default="mobile_bot_unnamed" name="mobile_3">
    <visual>
      <geometry>
        <cylinder length="0.5" radius="0.25"/>
      </geometry>
      <material name="blue"/>
      <origin rpy="0 0 0" xyz="0 0 0.25"/>
    </visual>
    <collision>
      <geometry>
        <cylinder length="0.5" radius="0.25"/>
      </geometry>
      <origin rpy="0 0 0" xyz="0 0 0.25"/>
    </collision>
  </link>
  <link name="mobile_3_temp"/>
  <link default="mobile_bot_unnamed" name="mobile_4">
    <visual>
      <geometry>
        <cylinder length="0.5" radius="0.25"/>
      </geometry>
      <material name="black"/>
      <origin rpy="0 0 0" xyz="0 0 0.25"/>
    </visual>
    <collision>
      <geometry>
        <cylinder length="0.5" radius="0.25"/>
      </geometry>
      <origin rpy="0 0 0" xyz="0 0 0.25"/>
    </collision>
  </link>
  <link name="mobile_4_temp"/>
  <!-- Mobile Robot 1 -->
  <joint name="mobile_1_1" type="prismatic">
    <parent link="world"/>
    <child link="mobile_1_temp"/>
    <limit effort="1000.0" lower="0" upper="10" velocity="1"/>
    <axis xyz="1 0 0"/>
    <origin rpy="0 0 0" xyz="0 0 0"/>
  </joint>
  <joint name="mobile_1_2" type="prismatic">
    <parent link="mobile_1_temp"/>
    <child link="mobile_1"/>
    <limit effort="1000.0" lower="0" upper="10" velocity="1"/>
    <axis xyz="0 1 0"/>
    <origin rpy="0 0 0" xyz="0 0 0"/>
  </joint>
  <!-- Mobile Robot 2 -->
  <joint name="mobile_2_1" type="prismatic">
    <parent link="world"/>
    <child link="mobile_2_temp"/>
    <limit effort="1000.0" lower="0" upper="10" velocity="1"/>
    <axis xyz="1 0 0"/>
    <origin rpy="0 0 0" xyz="0 0 0"/>
  </joint>
  <joint name="mobile_2_2" type="prismatic">
    <parent link="mobile_2_temp"/>
    <child link="mobile_2"/>
    <limit effort="1000.0" lower="0" upper="10" velocity="1"/>
    <axis xyz="0 1 0"/>
    <origin rpy="0 0 0" xyz="0 0 0"/>
  </joint>
  <!-- Mobile Robot 3 -->
  <joint name="mobile_3_1" type="prismatic">
    <parent link="world"/>
    <child link="mobile_3_temp"/>
    <limit effort="1000.0" lower="0" upper="10" velocity="1"/>
    <axis xyz="1 0 0"/>
    <origin rpy="0 0 0" xyz="0 0 0"/>
  </joint>
  <joint name="mobile_3_2" type="prismatic">
    <parent link="mobile_3_temp"/>
    <child link="mobile_3"/>
    <limit effort="1000.0" lower="0" upper="10" velocity="1"/>
    <axis xyz="0 1 0"/>
    <origin rpy="0 0 0" xyz="0 0 0"/>
  </joint>
  <!-- Mobile Robot 4 -->
  <joint name="mobile_4_1" type="prismatic">
    <parent link="world"/>
    <child link="mobile_4_temp"/>
    <limit effort="1000.0" lower="0" upper="10" velocity="1"/>
    <axis xyz="1 0 0"/>
    <origin rpy="0 0 0" xyz="0 0 0"/>
  </joint>
  <joint name="mobile_4_2" type="prismatic">
    <parent link="mobile_4_temp"/>
    <child link="mobile_4"/>
    <limit effort="1000.0" lower="0" upper="10" velocity="1"/>
    <axis xyz="0 1 0"/>
    <origin rpy="0 0 0" xyz="0 0 0"/>
  </joint>
</robot>
